<sdf version='1.6'>
  <world name='default'>
    <light name='sun' type='directional'>
      <cast_shadows>1</cast_shadows>
      <pose frame=''>0 0 10 0 -0 0</pose>
      <diffuse>0.8 0.8 0.8 1</diffuse>
      <specular>0.2 0.2 0.2 1</specular>
      <attenuation>
        <range>1000</range>
        <constant>0.9</constant>
        <linear>0.01</linear>
        <quadratic>0.001</quadratic>
      </attenuation>
      <direction>-0.5 0.1 -0.9</direction>
    </light>
    <model name='ground_plane'>
      <static>1</static>
      <link name='link'>
        <collision name='collision'>
          <geometry>
            <plane>
              <normal>0 0 1</normal>
              <size>100 100</size>
            </plane>
          </geometry>
          <surface>
            <friction>
              <ode>
                <mu>100</mu>
                <mu2>50</mu2>
              </ode>
              <torsional>
                <ode/>
              </torsional>
            </friction>
            <contact>
              <ode/>
            </contact>
            <bounce/>
          </surface>
          <max_contacts>10</max_contacts>
        </collision>
        <visual name='visual'>
          <cast_shadows>0</cast_shadows>
          <geometry>
            <plane>
              <normal>0 0 1</normal>
              <size>100 100</size>
            </plane>
          </geometry>
          <material>
            <script>
              <uri>file://media/materials/scripts/gazebo.material</uri>
              <name>Gazebo/Grey</name>
            </script>
          </material>
        </visual>
        <self_collide>0</self_collide>
        <kinematic>0</kinematic>
      </link>
    </model>
    <gravity>0 0 -9.8</gravity>
    <magnetic_field>6e-06 2.3e-05 -4.2e-05</magnetic_field>
    <atmosphere type='adiabatic'/>
    <physics name='default_physics' default='0' type='ode'>
      <max_step_size>0.001</max_step_size>
      <real_time_factor>1</real_time_factor>
      <real_time_update_rate>1000</real_time_update_rate>
    </physics>
    <scene>
      <ambient>0.4 0.4 0.4 1</ambient>
      <background>0.7 0.7 0.7 1</background>
      <shadows>1</shadows>
    </scene>
    <spherical_coordinates>
      <surface_model>EARTH_WGS84</surface_model>
      <latitude_deg>0</latitude_deg>
      <longitude_deg>0</longitude_deg>
      <elevation>0</elevation>
      <heading_deg>0</heading_deg>
    </spherical_coordinates>
    <model name='omni_silbot'>
      <link name='link_1'>
        <pose frame=''>-0.000639 0.000736 0 0 -0 0</pose>
        <inertial>
          <mass>1</mass>
          <inertia>
            <ixx>0.166667</ixx>
            <ixy>0</ixy>
            <ixz>0</ixz>
            <iyy>0.166667</iyy>
            <iyz>0</iyz>
            <izz>0.166667</izz>
          </inertia>
          <pose frame=''>0 0 0 0 -0 0</pose>
        </inertial>
        <gravity>1</gravity>
        <self_collide>0</self_collide>
        <kinematic>0</kinematic>
        <visual name='visual'>
          <pose frame=''>0 0 0 0 -0 0</pose>
          <geometry>
            <mesh>
              <uri>/home/minhhud/.gazebo/models/robots/meshes/base_link.stl</uri>
              <scale>1 1 1</scale>
            </mesh>
          </geometry>
          <material>
            <lighting>1</lighting>
            <script>
              <uri>file://media/materials/scripts/gazebo.material</uri>
              <name>Gazebo/Grey</name>
            </script>
            <ambient>0.3 0.3 0.3 1</ambient>
            <diffuse>0.7 0.7 0.7 1</diffuse>
            <specular>0.01 0.01 0.01 1</specular>
            <emissive>0 0 0 1</emissive>
            <shader type='vertex'>
              <normal_map>__default__</normal_map>
            </shader>
          </material>
          <transparency>0</transparency>
          <cast_shadows>1</cast_shadows>
        </visual>
        <collision name='collision'>
          <laser_retro>0</laser_retro>
          <max_contacts>10</max_contacts>
          <pose frame=''>0 0 0 0 -0 0</pose>
          <geometry>
            <mesh>
              <uri>/home/minhhud/.gazebo/models/robots/meshes/base_link.stl</uri>
              <scale>1 1 1</scale>
            </mesh>
          </geometry>
          <surface>
            <friction>
              <ode>
                <mu>1</mu>
                <mu2>1</mu2>
                <fdir1>0 0 0</fdir1>
                <slip1>0</slip1>
                <slip2>0</slip2>
              </ode>
              <torsional>
                <coefficient>1</coefficient>
                <patch_radius>0</patch_radius>
                <surface_radius>0</surface_radius>
                <use_patch_radius>1</use_patch_radius>
                <ode>
                  <slip>0</slip>
                </ode>
              </torsional>
            </friction>
            <bounce>
              <restitution_coefficient>0</restitution_coefficient>
              <threshold>1e+06</threshold>
            </bounce>
            <contact>
              <collide_without_contact>0</collide_without_contact>
              <collide_without_contact_bitmask>1</collide_without_contact_bitmask>
              <collide_bitmask>1</collide_bitmask>
              <ode>
                <soft_cfm>0</soft_cfm>
                <soft_erp>0.2</soft_erp>
                <kp>1e+13</kp>
                <kd>1</kd>
                <max_vel>0.01</max_vel>
                <min_depth>0</min_depth>
              </ode>
              <bullet>
                <split_impulse>1</split_impulse>
                <split_impulse_penetration_threshold>-0.01</split_impulse_penetration_threshold>
                <soft_cfm>0</soft_cfm>
                <soft_erp>0.2</soft_erp>
                <kp>1e+13</kp>
                <kd>1</kd>
              </bullet>
            </contact>
          </surface>
        </collision>
      </link>
      <model name='omni_wheel_model'>
        <link name='omni_wheel_rim_link'>
          <pose frame=''>0 0 0 0 -0 0</pose>
          <inertial>
            <mass>0.00835758</mass>
            <inertia>
              <ixx>9.40333e-07</ixx>
              <ixy>0</ixy>
              <ixz>0</ixz>
              <iyy>6.63684e-07</iyy>
              <iyz>0</iyz>
              <izz>6.63684e-07</izz>
            </inertia>
            <pose frame=''>0 -0.000343 0 0 -0 0</pose>
          </inertial>
          <self_collide>0</self_collide>
          <kinematic>0</kinematic>
          <gravity>1</gravity>
          <visual name='visual'>
            <pose frame=''>0 0 0 0 -0 0</pose>
            <geometry>
              <mesh>
                <uri>/home/minhhud/.gazebo/models/omni_wheel/rim.stl</uri>
                <scale>1 1 1</scale>
              </mesh>
            </geometry>
            <material>
              <lighting>1</lighting>
              <script>
                <name>Gazebo/Grey</name>
                <uri>__default__</uri>
              </script>
              <ambient>0.3 0.3 0.3 1</ambient>
              <diffuse>0.7 0.7 0.7 1</diffuse>
              <specular>0.01 0.01 0.01 1</specular>
              <emissive>0 0 0 1</emissive>
              <shader type='vertex'>
                <normal_map>__default__</normal_map>
              </shader>
            </material>
            <transparency>0</transparency>
            <cast_shadows>1</cast_shadows>
          </visual>
          <collision name='collision'>
            <laser_retro>0</laser_retro>
            <max_contacts>10</max_contacts>
            <pose frame=''>0 0 0 0 -0 0</pose>
            <geometry>
              <mesh>
                <uri>/home/minhhud/.gazebo/models/omni_wheel/rim.stl</uri>
                <scale>1 1 1</scale>
              </mesh>
            </geometry>
            <surface>
              <friction>
                <ode>
                  <mu>1</mu>
                  <mu2>1</mu2>
                  <fdir1>0 0 0</fdir1>
                  <slip1>0</slip1>
                  <slip2>0</slip2>
                </ode>
                <torsional>
                  <coefficient>1</coefficient>
                  <patch_radius>0</patch_radius>
                  <surface_radius>0</surface_radius>
                  <use_patch_radius>1</use_patch_radius>
                  <ode>
                    <slip>0</slip>
                  </ode>
                </torsional>
              </friction>
              <bounce>
                <restitution_coefficient>0</restitution_coefficient>
                <threshold>1e+06</threshold>
              </bounce>
              <contact>
                <collide_without_contact>0</collide_without_contact>
                <collide_without_contact_bitmask>1</collide_without_contact_bitmask>
                <collide_bitmask>1</collide_bitmask>
                <ode>
                  <soft_cfm>0</soft_cfm>
                  <soft_erp>0.2</soft_erp>
                  <kp>1e+13</kp>
                  <kd>1</kd>
                  <max_vel>0.01</max_vel>
                  <min_depth>0</min_depth>
                </ode>
                <bullet>
                  <split_impulse>1</split_impulse>
                  <split_impulse_penetration_threshold>-0.01</split_impulse_penetration_threshold>
                  <soft_cfm>0</soft_cfm>
                  <soft_erp>0.2</soft_erp>
                  <kp>1e+13</kp>
                  <kd>1</kd>
                </bullet>
              </contact>
            </surface>
          </collision>
        </link>
        <link name='omni_wheel_roller_e_link'>
          <pose frame=''>-0.0055 0.01355 0 0 -0 0</pose>
          <inertial>
            <mass>0.00113845</mass>
            <inertia>
              <ixx>2.53776e-08</ixx>
              <ixy>0</ixy>
              <ixz>0</ixz>
              <iyy>2.53776e-08</iyy>
              <iyz>0</iyz>
              <izz>1.47666e-08</izz>
            </inertia>
            <pose frame=''>0 0 0 0 -0 0</pose>
          </inertial>
          <self_collide>0</self_collide>
          <kinematic>0</kinematic>
          <visual name='visual'>
            <pose frame=''>0 0 0 0 -0 0</pose>
            <geometry>
              <mesh>
                <uri>/home/minhhud/.gazebo/models/omni_wheel/roller.stl</uri>
              </mesh>
            </geometry>
            <material>
              <lighting>1</lighting>
              <script>
                <name>Gazebo/Grey</name>
                <uri>__default__</uri>
              </script>
              <ambient>0.03 0.03 0.03 1</ambient>
              <diffuse>0.07 0.07 0.07 1</diffuse>
              <specular>0.001 0.001 0.001 1</specular>
              <emissive>0 0 0 1</emissive>
              <shader type='vertex'>
                <normal_map>__default__</normal_map>
              </shader>
            </material>
            <transparency>0</transparency>
            <cast_shadows>1</cast_shadows>
          </visual>
          <collision name='collision'>
            <laser_retro>0</laser_retro>
            <max_contacts>10</max_contacts>
            <pose frame=''>0 0 0 0 -0 0</pose>
            <geometry>
              <mesh>
                <uri>/home/minhhud/.gazebo/models/omni_wheel/roller.stl</uri>
                <scale>1 1 1</scale>
              </mesh>
            </geometry>
            <surface>
              <friction>
                <ode>
                  <mu>1</mu>
                  <mu2>1</mu2>
                  <fdir1>0 0 0</fdir1>
                  <slip1>0</slip1>
                  <slip2>0</slip2>
                </ode>
                <torsional>
                  <coefficient>1</coefficient>
                  <patch_radius>0</patch_radius>
                  <surface_radius>0</surface_radius>
                  <use_patch_radius>1</use_patch_radius>
                  <ode>
                    <slip>0</slip>
                  </ode>
                </torsional>
              </friction>
              <bounce>
                <restitution_coefficient>0</restitution_coefficient>
                <threshold>1e+06</threshold>
              </bounce>
              <contact>
                <collide_without_contact>0</collide_without_contact>
                <collide_without_contact_bitmask>1</collide_without_contact_bitmask>
                <collide_bitmask>1</collide_bitmask>
                <ode>
                  <soft_cfm>0</soft_cfm>
                  <soft_erp>0.2</soft_erp>
                  <kp>1e+13</kp>
                  <kd>1</kd>
                  <max_vel>0.01</max_vel>
                  <min_depth>0</min_depth>
                </ode>
                <bullet>
                  <split_impulse>1</split_impulse>
                  <split_impulse_penetration_threshold>-0.01</split_impulse_penetration_threshold>
                  <soft_cfm>0</soft_cfm>
                  <soft_erp>0.2</soft_erp>
                  <kp>1e+13</kp>
                  <kd>1</kd>
                </bullet>
              </contact>
            </surface>
          </collision>
        </link>
        <link name='omni_wheel_roller_ne_link'>
          <pose frame=''>0.0055 0.009581 0.009581 0.875398 -0 0</pose>
          <inertial>
            <mass>0.00113845</mass>
            <inertia>
              <ixx>2.53776e-08</ixx>
              <ixy>0</ixy>
              <ixz>0</ixz>
              <iyy>2.53776e-08</iyy>
              <iyz>0</iyz>
              <izz>1.47666e-08</izz>
            </inertia>
            <pose frame=''>0 0 0 0 -0 0</pose>
          </inertial>
          <self_collide>0</self_collide>
          <kinematic>0</kinematic>
          <visual name='visual'>
            <pose frame=''>0 0 0 0 -0 0</pose>
            <geometry>
              <mesh>
                <uri>/home/minhhud/.gazebo/models/omni_wheel/roller.stl</uri>
              </mesh>
            </geometry>
            <material>
              <lighting>1</lighting>
              <script>
                <name>Gazebo/Grey</name>
                <uri>__default__</uri>
              </script>
              <ambient>0.03 0.03 0.03 1</ambient>
              <diffuse>0.07 0.07 0.07 1</diffuse>
              <specular>0.001 0.001 0.001 1</specular>
              <emissive>0 0 0 1</emissive>
              <shader type='vertex'>
                <normal_map>__default__</normal_map>
              </shader>
            </material>
            <transparency>0</transparency>
            <cast_shadows>1</cast_shadows>
          </visual>
          <collision name='collision'>
            <laser_retro>0</laser_retro>
            <max_contacts>10</max_contacts>
            <pose frame=''>0 0 0 0 -0 0</pose>
            <geometry>
              <mesh>
                <uri>/home/minhhud/.gazebo/models/omni_wheel/roller.stl</uri>
                <scale>1 1 1</scale>
              </mesh>
            </geometry>
            <surface>
              <friction>
                <ode>
                  <mu>1</mu>
                  <mu2>1</mu2>
                  <fdir1>0 0 0</fdir1>
                  <slip1>0</slip1>
                  <slip2>0</slip2>
                </ode>
                <torsional>
                  <coefficient>1</coefficient>
                  <patch_radius>0</patch_radius>
                  <surface_radius>0</surface_radius>
                  <use_patch_radius>1</use_patch_radius>
                  <ode>
                    <slip>0</slip>
                  </ode>
                </torsional>
              </friction>
              <bounce>
                <restitution_coefficient>0</restitution_coefficient>
                <threshold>1e+06</threshold>
              </bounce>
              <contact>
                <collide_without_contact>0</collide_without_contact>
                <collide_without_contact_bitmask>1</collide_without_contact_bitmask>
                <collide_bitmask>1</collide_bitmask>
                <ode>
                  <soft_cfm>0</soft_cfm>
                  <soft_erp>0.2</soft_erp>
                  <kp>1e+13</kp>
                  <kd>1</kd>
                  <max_vel>0.01</max_vel>
                  <min_depth>0</min_depth>
                </ode>
                <bullet>
                  <split_impulse>1</split_impulse>
                  <split_impulse_penetration_threshold>-0.01</split_impulse_penetration_threshold>
                  <soft_cfm>0</soft_cfm>
                  <soft_erp>0.2</soft_erp>
                  <kp>1e+13</kp>
                  <kd>1</kd>
                </bullet>
              </contact>
            </surface>
          </collision>
        </link>
        <link name='omni_wheel_roller_n_link'>
          <pose frame=''>-0.0055 0 0.01355 1.5708 -0 0</pose>
          <inertial>
            <mass>0.00113845</mass>
            <inertia>
              <ixx>2.53776e-08</ixx>
              <ixy>0</ixy>
              <ixz>0</ixz>
              <iyy>2.53776e-08</iyy>
              <iyz>0</iyz>
              <izz>1.47666e-08</izz>
            </inertia>
            <pose frame=''>0 0 0 0 -0 0</pose>
          </inertial>
          <self_collide>0</self_collide>
          <kinematic>0</kinematic>
          <gravity>1</gravity>
          <visual name='visual'>
            <pose frame=''>0 0 0 0 -0 0</pose>
            <geometry>
              <mesh>
                <uri>/home/minhhud/.gazebo/models/omni_wheel/roller.stl</uri>
                <scale>1 1 1</scale>
              </mesh>
            </geometry>
            <material>
              <lighting>1</lighting>
              <script>
                <name>Gazebo/Grey</name>
                <uri>__default__</uri>
              </script>
              <ambient>0.03 0.03 0.03 1</ambient>
              <diffuse>0.07 0.07 0.07 1</diffuse>
              <specular>0.001 0.001 0.001 1</specular>
              <emissive>0 0 0 1</emissive>
              <shader type='vertex'>
                <normal_map>__default__</normal_map>
              </shader>
            </material>
            <transparency>0</transparency>
            <cast_shadows>1</cast_shadows>
          </visual>
          <collision name='collision'>
            <laser_retro>0</laser_retro>
            <max_contacts>10</max_contacts>
            <pose frame=''>0 0 0 0 -0 0</pose>
            <geometry>
              <mesh>
                <uri>/home/minhhud/.gazebo/models/omni_wheel/roller.stl</uri>
                <scale>1 1 1</scale>
              </mesh>
            </geometry>
            <surface>
              <friction>
                <ode>
                  <mu>1</mu>
                  <mu2>1</mu2>
                  <fdir1>0 0 0</fdir1>
                  <slip1>0</slip1>
                  <slip2>0</slip2>
                </ode>
                <torsional>
                  <coefficient>1</coefficient>
                  <patch_radius>0</patch_radius>
                  <surface_radius>0</surface_radius>
                  <use_patch_radius>1</use_patch_radius>
                  <ode>
                    <slip>0</slip>
                  </ode>
                </torsional>
              </friction>
              <bounce>
                <restitution_coefficient>0</restitution_coefficient>
                <threshold>1e+06</threshold>
              </bounce>
              <contact>
                <collide_without_contact>0</collide_without_contact>
                <collide_without_contact_bitmask>1</collide_without_contact_bitmask>
                <collide_bitmask>1</collide_bitmask>
                <ode>
                  <soft_cfm>0</soft_cfm>
                  <soft_erp>0.2</soft_erp>
                  <kp>1e+13</kp>
                  <kd>1</kd>
                  <max_vel>0.01</max_vel>
                  <min_depth>0</min_depth>
                </ode>
                <bullet>
                  <split_impulse>1</split_impulse>
                  <split_impulse_penetration_threshold>-0.01</split_impulse_penetration_threshold>
                  <soft_cfm>0</soft_cfm>
                  <soft_erp>0.2</soft_erp>
                  <kp>1e+13</kp>
                  <kd>1</kd>
                </bullet>
              </contact>
            </surface>
          </collision>
        </link>
        <link name='omni_wheel_roller_nw_link'>
          <pose frame=''>0.0055 -0.009581 0.009581 2.35619 -0 0</pose>
          <inertial>
            <mass>0.00113845</mass>
            <inertia>
              <ixx>2.53776e-08</ixx>
              <ixy>0</ixy>
              <ixz>0</ixz>
              <iyy>2.53776e-08</iyy>
              <iyz>0</iyz>
              <izz>1.47666e-08</izz>
            </inertia>
            <pose frame=''>0 0 0 0 -0 0</pose>
          </inertial>
          <self_collide>0</self_collide>
          <kinematic>0</kinematic>
          <gravity>1</gravity>
          <visual name='visual'>
            <pose frame=''>0 0 0 0 -0 0</pose>
            <geometry>
              <mesh>
                <uri>/home/minhhud/.gazebo/models/omni_wheel/roller.stl</uri>
              </mesh>
            </geometry>
            <material>
              <lighting>1</lighting>
              <script>
                <name>Gazebo/Grey</name>
                <uri>__default__</uri>
              </script>
              <ambient>0.03 0.03 0.03 1</ambient>
              <diffuse>0.07 0.07 0.07 1</diffuse>
              <specular>0.001 0.001 0.001 1</specular>
              <emissive>0 0 0 1</emissive>
              <shader type='vertex'>
                <normal_map>__default__</normal_map>
              </shader>
            </material>
            <transparency>0</transparency>
            <cast_shadows>1</cast_shadows>
          </visual>
          <collision name='collision'>
            <laser_retro>0</laser_retro>
            <max_contacts>10</max_contacts>
            <pose frame=''>0 0 0 0 -0 0</pose>
            <geometry>
              <mesh>
                <uri>/home/minhhud/.gazebo/models/omni_wheel/roller.stl</uri>
                <scale>1 1 1</scale>
              </mesh>
            </geometry>
            <surface>
              <friction>
                <ode>
                  <mu>1</mu>
                  <mu2>1</mu2>
                  <fdir1>0 0 0</fdir1>
                  <slip1>0</slip1>
                  <slip2>0</slip2>
                </ode>
                <torsional>
                  <coefficient>1</coefficient>
                  <patch_radius>0</patch_radius>
                  <surface_radius>0</surface_radius>
                  <use_patch_radius>1</use_patch_radius>
                  <ode>
                    <slip>0</slip>
                  </ode>
                </torsional>
              </friction>
              <bounce>
                <restitution_coefficient>0</restitution_coefficient>
                <threshold>1e+06</threshold>
              </bounce>
              <contact>
                <collide_without_contact>0</collide_without_contact>
                <collide_without_contact_bitmask>1</collide_without_contact_bitmask>
                <collide_bitmask>1</collide_bitmask>
                <ode>
                  <soft_cfm>0</soft_cfm>
                  <soft_erp>0.2</soft_erp>
                  <kp>1e+13</kp>
                  <kd>1</kd>
                  <max_vel>0.01</max_vel>
                  <min_depth>0</min_depth>
                </ode>
                <bullet>
                  <split_impulse>1</split_impulse>
                  <split_impulse_penetration_threshold>-0.01</split_impulse_penetration_threshold>
                  <soft_cfm>0</soft_cfm>
                  <soft_erp>0.2</soft_erp>
                  <kp>1e+13</kp>
                  <kd>1</kd>
                </bullet>
              </contact>
            </surface>
          </collision>
        </link>
        <link name='omni_wheel_roller_w_link'>
          <pose frame=''>-0.0055 -0.01355 0 -3.14159 0 0</pose>
          <inertial>
            <mass>0.00113845</mass>
            <inertia>
              <ixx>2.53776e-08</ixx>
              <ixy>0</ixy>
              <ixz>0</ixz>
              <iyy>2.53776e-08</iyy>
              <iyz>0</iyz>
              <izz>1.47666e-08</izz>
            </inertia>
            <pose frame=''>0 0 0 0 -0 0</pose>
          </inertial>
          <self_collide>0</self_collide>
          <kinematic>0</kinematic>
          <gravity>1</gravity>
          <visual name='visual'>
            <pose frame=''>0 0 0 0 -0 0</pose>
            <geometry>
              <mesh>
                <uri>/home/minhhud/.gazebo/models/omni_wheel/roller.stl</uri>
              </mesh>
            </geometry>
            <material>
              <lighting>1</lighting>
              <script>
                <name>Gazebo/Grey</name>
                <uri>__default__</uri>
              </script>
              <ambient>0.03 0.03 0.03 1</ambient>
              <diffuse>0.07 0.07 0.07 1</diffuse>
              <specular>0.001 0.001 0.001 1</specular>
              <emissive>0 0 0 1</emissive>
              <shader type='vertex'>
                <normal_map>__default__</normal_map>
              </shader>
            </material>
            <transparency>0</transparency>
            <cast_shadows>1</cast_shadows>
          </visual>
          <collision name='collision'>
            <laser_retro>0</laser_retro>
            <max_contacts>10</max_contacts>
            <pose frame=''>0 0 0 0 -0 0</pose>
            <geometry>
              <mesh>
                <uri>/home/minhhud/.gazebo/models/omni_wheel/roller.stl</uri>
                <scale>1 1 1</scale>
              </mesh>
            </geometry>
            <surface>
              <friction>
                <ode>
                  <mu>1</mu>
                  <mu2>1</mu2>
                  <fdir1>0 0 0</fdir1>
                  <slip1>0</slip1>
                  <slip2>0</slip2>
                </ode>
                <torsional>
                  <coefficient>1</coefficient>
                  <patch_radius>0</patch_radius>
                  <surface_radius>0</surface_radius>
                  <use_patch_radius>1</use_patch_radius>
                  <ode>
                    <slip>0</slip>
                  </ode>
                </torsional>
              </friction>
              <bounce>
                <restitution_coefficient>0</restitution_coefficient>
                <threshold>1e+06</threshold>
              </bounce>
              <contact>
                <collide_without_contact>0</collide_without_contact>
                <collide_without_contact_bitmask>1</collide_without_contact_bitmask>
                <collide_bitmask>1</collide_bitmask>
                <ode>
                  <soft_cfm>0</soft_cfm>
                  <soft_erp>0.2</soft_erp>
                  <kp>1e+13</kp>
                  <kd>1</kd>
                  <max_vel>0.01</max_vel>
                  <min_depth>0</min_depth>
                </ode>
                <bullet>
                  <split_impulse>1</split_impulse>
                  <split_impulse_penetration_threshold>-0.01</split_impulse_penetration_threshold>
                  <soft_cfm>0</soft_cfm>
                  <soft_erp>0.2</soft_erp>
                  <kp>1e+13</kp>
                  <kd>1</kd>
                </bullet>
              </contact>
            </surface>
          </collision>
        </link>
        <link name='omni_wheel_roller_sw_link'>
          <pose frame=''>0.0055 -0.009581 -0.009581 -2.35619 0 0</pose>
          <inertial>
            <mass>0.00113845</mass>
            <inertia>
              <ixx>2.53776e-08</ixx>
              <ixy>0</ixy>
              <ixz>0</ixz>
              <iyy>2.53776e-08</iyy>
              <iyz>0</iyz>
              <izz>1.47666e-08</izz>
            </inertia>
            <pose frame=''>0 0 0 0 -0 0</pose>
          </inertial>
          <self_collide>0</self_collide>
          <kinematic>0</kinematic>
          <gravity>1</gravity>
          <visual name='visual'>
            <pose frame=''>0 0 0 0 -0 0</pose>
            <geometry>
              <mesh>
                <uri>/home/minhhud/.gazebo/models/omni_wheel/roller.stl</uri>
                <scale>1 1 1</scale>
              </mesh>
            </geometry>
            <material>
              <lighting>1</lighting>
              <script>
                <name>Gazebo/Grey</name>
                <uri>__default__</uri>
              </script>
              <ambient>0.03 0.03 0.03 1</ambient>
              <diffuse>0.07 0.07 0.07 1</diffuse>
              <specular>0.001 0.001 0.001 1</specular>
              <emissive>0 0 0 1</emissive>
              <shader type='vertex'>
                <normal_map>__default__</normal_map>
              </shader>
            </material>
            <transparency>0</transparency>
            <cast_shadows>1</cast_shadows>
          </visual>
          <collision name='collision'>
            <laser_retro>0</laser_retro>
            <max_contacts>10</max_contacts>
            <pose frame=''>0 0 0 0 -0 0</pose>
            <geometry>
              <mesh>
                <uri>/home/minhhud/.gazebo/models/omni_wheel/roller.stl</uri>
                <scale>1 1 1</scale>
              </mesh>
            </geometry>
            <surface>
              <friction>
                <ode>
                  <mu>1</mu>
                  <mu2>1</mu2>
                  <fdir1>0 0 0</fdir1>
                  <slip1>0</slip1>
                  <slip2>0</slip2>
                </ode>
                <torsional>
                  <coefficient>1</coefficient>
                  <patch_radius>0</patch_radius>
                  <surface_radius>0</surface_radius>
                  <use_patch_radius>1</use_patch_radius>
                  <ode>
                    <slip>0</slip>
                  </ode>
                </torsional>
              </friction>
              <bounce>
                <restitution_coefficient>0</restitution_coefficient>
                <threshold>1e+06</threshold>
              </bounce>
              <contact>
                <collide_without_contact>0</collide_without_contact>
                <collide_without_contact_bitmask>1</collide_without_contact_bitmask>
                <collide_bitmask>1</collide_bitmask>
                <ode>
                  <soft_cfm>0</soft_cfm>
                  <soft_erp>0.2</soft_erp>
                  <kp>1e+13</kp>
                  <kd>1</kd>
                  <max_vel>0.01</max_vel>
                  <min_depth>0</min_depth>
                </ode>
                <bullet>
                  <split_impulse>1</split_impulse>
                  <split_impulse_penetration_threshold>-0.01</split_impulse_penetration_threshold>
                  <soft_cfm>0</soft_cfm>
                  <soft_erp>0.2</soft_erp>
                  <kp>1e+13</kp>
                  <kd>1</kd>
                </bullet>
              </contact>
            </surface>
          </collision>
        </link>
        <link name='omni_wheel_roller_s_link'>
          <pose frame=''>-0.0055 0 -0.01355 -1.5708 0 0</pose>
          <inertial>
            <mass>0.00113845</mass>
            <inertia>
              <ixx>2.53776e-08</ixx>
              <ixy>0</ixy>
              <ixz>0</ixz>
              <iyy>2.53776e-08</iyy>
              <iyz>0</iyz>
              <izz>1.47666e-08</izz>
            </inertia>
            <pose frame=''>0 0 0 0 -0 0</pose>
          </inertial>
          <self_collide>0</self_collide>
          <kinematic>0</kinematic>
          <gravity>1</gravity>
          <visual name='visual'>
            <pose frame=''>0 0 0 0 -0 0</pose>
            <geometry>
              <mesh>
                <uri>/home/minhhud/.gazebo/models/omni_wheel/roller.stl</uri>
              </mesh>
            </geometry>
            <material>
              <lighting>1</lighting>
              <script>
                <name>Gazebo/Grey</name>
                <uri>__default__</uri>
              </script>
              <ambient>0.03 0.03 0.03 1</ambient>
              <diffuse>0.07 0.07 0.07 1</diffuse>
              <specular>0.001 0.001 0.001 1</specular>
              <emissive>0 0 0 1</emissive>
              <shader type='vertex'>
                <normal_map>__default__</normal_map>
              </shader>
            </material>
            <transparency>0</transparency>
            <cast_shadows>1</cast_shadows>
          </visual>
          <collision name='collision'>
            <laser_retro>0</laser_retro>
            <max_contacts>10</max_contacts>
            <pose frame=''>0 0 0 0 -0 0</pose>
            <geometry>
              <mesh>
                <uri>/home/minhhud/.gazebo/models/omni_wheel/roller.stl</uri>
                <scale>1 1 1</scale>
              </mesh>
            </geometry>
            <surface>
              <friction>
                <ode>
                  <mu>1</mu>
                  <mu2>1</mu2>
                  <fdir1>0 0 0</fdir1>
                  <slip1>0</slip1>
                  <slip2>0</slip2>
                </ode>
                <torsional>
                  <coefficient>1</coefficient>
                  <patch_radius>0</patch_radius>
                  <surface_radius>0</surface_radius>
                  <use_patch_radius>1</use_patch_radius>
                  <ode>
                    <slip>0</slip>
                  </ode>
                </torsional>
              </friction>
              <bounce>
                <restitution_coefficient>0</restitution_coefficient>
                <threshold>1e+06</threshold>
              </bounce>
              <contact>
                <collide_without_contact>0</collide_without_contact>
                <collide_without_contact_bitmask>1</collide_without_contact_bitmask>
                <collide_bitmask>1</collide_bitmask>
                <ode>
                  <soft_cfm>0</soft_cfm>
                  <soft_erp>0.2</soft_erp>
                  <kp>1e+13</kp>
                  <kd>1</kd>
                  <max_vel>0.01</max_vel>
                  <min_depth>0</min_depth>
                </ode>
                <bullet>
                  <split_impulse>1</split_impulse>
                  <split_impulse_penetration_threshold>-0.01</split_impulse_penetration_threshold>
                  <soft_cfm>0</soft_cfm>
                  <soft_erp>0.2</soft_erp>
                  <kp>1e+13</kp>
                  <kd>1</kd>
                </bullet>
              </contact>
            </surface>
          </collision>
        </link>
        <link name='omni_wheel_roller_se_link'>
          <pose frame=''>0.0055 0.009581 -0.009581 -0.875398 0 0</pose>
          <inertial>
            <mass>0.00113845</mass>
            <inertia>
              <ixx>2.53776e-08</ixx>
              <ixy>0</ixy>
              <ixz>0</ixz>
              <iyy>2.53776e-08</iyy>
              <iyz>0</iyz>
              <izz>1.47666e-08</izz>
            </inertia>
            <pose frame=''>0 0 0 0 -0 0</pose>
          </inertial>
          <self_collide>0</self_collide>
          <kinematic>0</kinematic>
          <gravity>1</gravity>
          <visual name='visual'>
            <pose frame=''>0 0 0 0 -0 0</pose>
            <geometry>
              <mesh>
                <uri>/home/minhhud/.gazebo/models/omni_wheel/roller.stl</uri>
                <scale>1 1 1</scale>
              </mesh>
            </geometry>
            <material>
              <lighting>1</lighting>
              <script>
                <name>Gazebo/Grey</name>
                <uri>__default__</uri>
              </script>
              <ambient>0.03 0.03 0.03 1</ambient>
              <diffuse>0.07 0.07 0.07 1</diffuse>
              <specular>0.001 0.001 0.001 1</specular>
              <emissive>0 0 0 1</emissive>
              <shader type='vertex'>
                <normal_map>__default__</normal_map>
              </shader>
            </material>
            <transparency>0</transparency>
            <cast_shadows>1</cast_shadows>
          </visual>
          <collision name='collision'>
            <laser_retro>0</laser_retro>
            <max_contacts>10</max_contacts>
            <pose frame=''>0 0 0 0 -0 0</pose>
            <geometry>
              <mesh>
                <uri>/home/minhhud/.gazebo/models/omni_wheel/roller.stl</uri>
                <scale>1 1 1</scale>
              </mesh>
            </geometry>
            <surface>
              <friction>
                <ode>
                  <mu>1</mu>
                  <mu2>1</mu2>
                  <fdir1>0 0 0</fdir1>
                  <slip1>0</slip1>
                  <slip2>0</slip2>
                </ode>
                <torsional>
                  <coefficient>1</coefficient>
                  <patch_radius>0</patch_radius>
                  <surface_radius>0</surface_radius>
                  <use_patch_radius>1</use_patch_radius>
                  <ode>
                    <slip>0</slip>
                  </ode>
                </torsional>
              </friction>
              <bounce>
                <restitution_coefficient>0</restitution_coefficient>
                <threshold>1e+06</threshold>
              </bounce>
              <contact>
                <collide_without_contact>0</collide_without_contact>
                <collide_without_contact_bitmask>1</collide_without_contact_bitmask>
                <collide_bitmask>1</collide_bitmask>
                <ode>
                  <soft_cfm>0</soft_cfm>
                  <soft_erp>0.2</soft_erp>
                  <kp>1e+13</kp>
                  <kd>1</kd>
                  <max_vel>0.01</max_vel>
                  <min_depth>0</min_depth>
                </ode>
                <bullet>
                  <split_impulse>1</split_impulse>
                  <split_impulse_penetration_threshold>-0.01</split_impulse_penetration_threshold>
                  <soft_cfm>0</soft_cfm>
                  <soft_erp>0.2</soft_erp>
                  <kp>1e+13</kp>
                  <kd>1</kd>
                </bullet>
              </contact>
            </surface>
          </collision>
        </link>
        <joint name='omni_wheel_s_joint' type='revolute'>
          <parent>omni_wheel_rim_link</parent>
          <child>omni_wheel_roller_s_link</child>
          <pose frame=''>0 0 0 0 -0 1.5708</pose>
          <axis>
            <xyz>0 0 1</xyz>
            <use_parent_model_frame>0</use_parent_model_frame>
            <limit>
              <lower>-1.79769e+308</lower>
              <upper>1.79769e+308</upper>
              <effort>-1</effort>
              <velocity>-1</velocity>
            </limit>
            <dynamics>
              <spring_reference>0</spring_reference>
              <spring_stiffness>0</spring_stiffness>
              <damping>0</damping>
              <friction>0</friction>
            </dynamics>
          </axis>
          <physics>
            <ode>
              <limit>
                <cfm>0</cfm>
                <erp>0.2</erp>
              </limit>
              <suspension>
                <cfm>0</cfm>
                <erp>0.2</erp>
              </suspension>
            </ode>
          </physics>
        </joint>
        <joint name='omni_wheel_se_joint' type='revolute'>
          <parent>omni_wheel_rim_link</parent>
          <child>omni_wheel_roller_se_link</child>
          <pose frame=''>0 0 0 0 -0 1.5708</pose>
          <axis>
            <xyz>0 0 1</xyz>
            <use_parent_model_frame>0</use_parent_model_frame>
            <limit>
              <lower>-1.79769e+308</lower>
              <upper>1.79769e+308</upper>
              <effort>-1</effort>
              <velocity>-1</velocity>
            </limit>
            <dynamics>
              <spring_reference>0</spring_reference>
              <spring_stiffness>0</spring_stiffness>
              <damping>0</damping>
              <friction>0</friction>
            </dynamics>
          </axis>
          <physics>
            <ode>
              <limit>
                <cfm>0</cfm>
                <erp>0.2</erp>
              </limit>
              <suspension>
                <cfm>0</cfm>
                <erp>0.2</erp>
              </suspension>
            </ode>
          </physics>
        </joint>
        <joint name='omni_wheel_e_joint' type='revolute'>
          <parent>omni_wheel_rim_link</parent>
          <child>omni_wheel_roller_e_link</child>
          <pose frame=''>0 0 0 0 -0 1.5708</pose>
          <axis>
            <xyz>0 0 1</xyz>
            <use_parent_model_frame>0</use_parent_model_frame>
            <limit>
              <lower>-1.79769e+308</lower>
              <upper>1.79769e+308</upper>
              <effort>-1</effort>
              <velocity>-1</velocity>
            </limit>
            <dynamics>
              <spring_reference>0</spring_reference>
              <spring_stiffness>0</spring_stiffness>
              <damping>0</damping>
              <friction>0</friction>
            </dynamics>
          </axis>
          <physics>
            <ode>
              <limit>
                <cfm>0</cfm>
                <erp>0.2</erp>
              </limit>
              <suspension>
                <cfm>0</cfm>
                <erp>0.2</erp>
              </suspension>
            </ode>
          </physics>
        </joint>
        <joint name='omni_wheel_ne_joint' type='revolute'>
          <parent>omni_wheel_rim_link</parent>
          <child>omni_wheel_roller_ne_link</child>
          <pose frame=''>0 0 0 0 -0 1.5708</pose>
          <axis>
            <xyz>0 0 1</xyz>
            <use_parent_model_frame>0</use_parent_model_frame>
            <limit>
              <lower>-1.79769e+308</lower>
              <upper>1.79769e+308</upper>
              <effort>-1</effort>
              <velocity>-1</velocity>
            </limit>
            <dynamics>
              <spring_reference>0</spring_reference>
              <spring_stiffness>0</spring_stiffness>
              <damping>0</damping>
              <friction>0</friction>
            </dynamics>
          </axis>
          <physics>
            <ode>
              <limit>
                <cfm>0</cfm>
                <erp>0.2</erp>
              </limit>
              <suspension>
                <cfm>0</cfm>
                <erp>0.2</erp>
              </suspension>
            </ode>
          </physics>
        </joint>
        <joint name='omni_wheel_n_joint' type='revolute'>
          <parent>omni_wheel_rim_link</parent>
          <child>omni_wheel_roller_n_link</child>
          <pose frame=''>0 0 0 0 -0 1.5708</pose>
          <axis>
            <xyz>0 0 1</xyz>
            <use_parent_model_frame>0</use_parent_model_frame>
            <limit>
              <lower>-1.79769e+308</lower>
              <upper>1.79769e+308</upper>
              <effort>-1</effort>
              <velocity>-1</velocity>
            </limit>
            <dynamics>
              <spring_reference>0</spring_reference>
              <spring_stiffness>0</spring_stiffness>
              <damping>0</damping>
              <friction>0</friction>
            </dynamics>
          </axis>
          <physics>
            <ode>
              <limit>
                <cfm>0</cfm>
                <erp>0.2</erp>
              </limit>
              <suspension>
                <cfm>0</cfm>
                <erp>0.2</erp>
              </suspension>
            </ode>
          </physics>
        </joint>
        <joint name='omni_wheel_nw_joint' type='revolute'>
          <parent>omni_wheel_rim_link</parent>
          <child>omni_wheel_roller_nw_link</child>
          <pose frame=''>0 0 0 0 -0 1.5708</pose>
          <axis>
            <xyz>0 0 1</xyz>
            <use_parent_model_frame>0</use_parent_model_frame>
            <limit>
              <lower>-1.79769e+308</lower>
              <upper>1.79769e+308</upper>
              <effort>-1</effort>
              <velocity>-1</velocity>
            </limit>
            <dynamics>
              <spring_reference>0</spring_reference>
              <spring_stiffness>0</spring_stiffness>
              <damping>0</damping>
              <friction>0</friction>
            </dynamics>
          </axis>
          <physics>
            <ode>
              <limit>
                <cfm>0</cfm>
                <erp>0.2</erp>
              </limit>
              <suspension>
                <cfm>0</cfm>
                <erp>0.2</erp>
              </suspension>
            </ode>
          </physics>
        </joint>
        <joint name='omni_wheel_w_joint' type='revolute'>
          <parent>omni_wheel_rim_link</parent>
          <child>omni_wheel_roller_w_link</child>
          <pose frame=''>0 0 0 0 -0 1.5708</pose>
          <axis>
            <xyz>0 0 1</xyz>
            <use_parent_model_frame>0</use_parent_model_frame>
            <limit>
              <lower>-1.79769e+308</lower>
              <upper>1.79769e+308</upper>
              <effort>-1</effort>
              <velocity>-1</velocity>
            </limit>
            <dynamics>
              <spring_reference>0</spring_reference>
              <spring_stiffness>0</spring_stiffness>
              <damping>0</damping>
              <friction>0</friction>
            </dynamics>
          </axis>
          <physics>
            <ode>
              <limit>
                <cfm>0</cfm>
                <erp>0.2</erp>
              </limit>
              <suspension>
                <cfm>0</cfm>
                <erp>0.2</erp>
              </suspension>
            </ode>
          </physics>
        </joint>
        <joint name='omni_wheel_sw_joint' type='revolute'>
          <parent>omni_wheel_rim_link</parent>
          <child>omni_wheel_roller_sw_link</child>
          <pose frame=''>0 0 0 0 -0 1.5708</pose>
          <axis>
            <xyz>0 0 1</xyz>
            <use_parent_model_frame>0</use_parent_model_frame>
            <limit>
              <lower>-1.79769e+308</lower>
              <upper>1.79769e+308</upper>
              <effort>-1</effort>
              <velocity>-1</velocity>
            </limit>
            <dynamics>
              <spring_reference>0</spring_reference>
              <spring_stiffness>0</spring_stiffness>
              <damping>0</damping>
              <friction>0</friction>
            </dynamics>
          </axis>
          <physics>
            <ode>
              <limit>
                <cfm>0</cfm>
                <erp>0.2</erp>
              </limit>
              <suspension>
                <cfm>0</cfm>
                <erp>0.2</erp>
              </suspension>
            </ode>
          </physics>
        </joint>
        <static>0</static>
        <allow_auto_disable>1</allow_auto_disable>
        <pose frame=''>-0.149207 -0.091032 0 0 -0 0.469574</pose>
      </model>
      <model name='omni_wheel_model_0'>
        <link name='omni_wheel_rim_link'>
          <pose frame=''>0 0 0 0 -0 0</pose>
          <inertial>
            <mass>0.00835758</mass>
            <inertia>
              <ixx>9.40333e-07</ixx>
              <ixy>0</ixy>
              <ixz>0</ixz>
              <iyy>6.63684e-07</iyy>
              <iyz>0</iyz>
              <izz>6.63684e-07</izz>
            </inertia>
            <pose frame=''>0 -0.000343 0 0 -0 0</pose>
          </inertial>
          <self_collide>0</self_collide>
          <kinematic>0</kinematic>
          <gravity>1</gravity>
          <visual name='visual'>
            <pose frame=''>0 0 0 0 -0 0</pose>
            <geometry>
              <mesh>
                <uri>/home/minhhud/.gazebo/models/omni_wheel/rim.stl</uri>
                <scale>1 1 1</scale>
              </mesh>
            </geometry>
            <material>
              <lighting>1</lighting>
              <script>
                <name>Gazebo/Grey</name>
                <uri>__default__</uri>
              </script>
              <ambient>0.3 0.3 0.3 1</ambient>
              <diffuse>0.7 0.7 0.7 1</diffuse>
              <specular>0.01 0.01 0.01 1</specular>
              <emissive>0 0 0 1</emissive>
              <shader type='vertex'>
                <normal_map>__default__</normal_map>
              </shader>
            </material>
            <transparency>0</transparency>
            <cast_shadows>1</cast_shadows>
          </visual>
          <collision name='collision'>
            <laser_retro>0</laser_retro>
            <max_contacts>10</max_contacts>
            <pose frame=''>0 0 0 0 -0 0</pose>
            <geometry>
              <mesh>
                <uri>/home/minhhud/.gazebo/models/omni_wheel/rim.stl</uri>
                <scale>1 1 1</scale>
              </mesh>
            </geometry>
            <surface>
              <friction>
                <ode>
                  <mu>1</mu>
                  <mu2>1</mu2>
                  <fdir1>0 0 0</fdir1>
                  <slip1>0</slip1>
                  <slip2>0</slip2>
                </ode>
                <torsional>
                  <coefficient>1</coefficient>
                  <patch_radius>0</patch_radius>
                  <surface_radius>0</surface_radius>
                  <use_patch_radius>1</use_patch_radius>
                  <ode>
                    <slip>0</slip>
                  </ode>
                </torsional>
              </friction>
              <bounce>
                <restitution_coefficient>0</restitution_coefficient>
                <threshold>1e+06</threshold>
              </bounce>
              <contact>
                <collide_without_contact>0</collide_without_contact>
                <collide_without_contact_bitmask>1</collide_without_contact_bitmask>
                <collide_bitmask>1</collide_bitmask>
                <ode>
                  <soft_cfm>0</soft_cfm>
                  <soft_erp>0.2</soft_erp>
                  <kp>1e+13</kp>
                  <kd>1</kd>
                  <max_vel>0.01</max_vel>
                  <min_depth>0</min_depth>
                </ode>
                <bullet>
                  <split_impulse>1</split_impulse>
                  <split_impulse_penetration_threshold>-0.01</split_impulse_penetration_threshold>
                  <soft_cfm>0</soft_cfm>
                  <soft_erp>0.2</soft_erp>
                  <kp>1e+13</kp>
                  <kd>1</kd>
                </bullet>
              </contact>
            </surface>
          </collision>
        </link>
        <link name='omni_wheel_roller_e_link'>
          <pose frame=''>-0.0055 0.01355 0 0 -0 0</pose>
          <inertial>
            <mass>0.00113845</mass>
            <inertia>
              <ixx>2.53776e-08</ixx>
              <ixy>0</ixy>
              <ixz>0</ixz>
              <iyy>2.53776e-08</iyy>
              <iyz>0</iyz>
              <izz>1.47666e-08</izz>
            </inertia>
            <pose frame=''>0 0 0 0 -0 0</pose>
          </inertial>
          <self_collide>0</self_collide>
          <kinematic>0</kinematic>
          <visual name='visual'>
            <pose frame=''>0 0 0 0 -0 0</pose>
            <geometry>
              <mesh>
                <uri>/home/minhhud/.gazebo/models/omni_wheel/roller.stl</uri>
              </mesh>
            </geometry>
            <material>
              <lighting>1</lighting>
              <script>
                <name>Gazebo/Grey</name>
                <uri>__default__</uri>
              </script>
              <ambient>0.03 0.03 0.03 1</ambient>
              <diffuse>0.07 0.07 0.07 1</diffuse>
              <specular>0.001 0.001 0.001 1</specular>
              <emissive>0 0 0 1</emissive>
              <shader type='vertex'>
                <normal_map>__default__</normal_map>
              </shader>
            </material>
            <transparency>0</transparency>
            <cast_shadows>1</cast_shadows>
          </visual>
          <collision name='collision'>
            <laser_retro>0</laser_retro>
            <max_contacts>10</max_contacts>
            <pose frame=''>0 0 0 0 -0 0</pose>
            <geometry>
              <mesh>
                <uri>/home/minhhud/.gazebo/models/omni_wheel/roller.stl</uri>
                <scale>1 1 1</scale>
              </mesh>
            </geometry>
            <surface>
              <friction>
                <ode>
                  <mu>1</mu>
                  <mu2>1</mu2>
                  <fdir1>0 0 0</fdir1>
                  <slip1>0</slip1>
                  <slip2>0</slip2>
                </ode>
                <torsional>
                  <coefficient>1</coefficient>
                  <patch_radius>0</patch_radius>
                  <surface_radius>0</surface_radius>
                  <use_patch_radius>1</use_patch_radius>
                  <ode>
                    <slip>0</slip>
                  </ode>
                </torsional>
              </friction>
              <bounce>
                <restitution_coefficient>0</restitution_coefficient>
                <threshold>1e+06</threshold>
              </bounce>
              <contact>
                <collide_without_contact>0</collide_without_contact>
                <collide_without_contact_bitmask>1</collide_without_contact_bitmask>
                <collide_bitmask>1</collide_bitmask>
                <ode>
                  <soft_cfm>0</soft_cfm>
                  <soft_erp>0.2</soft_erp>
                  <kp>1e+13</kp>
                  <kd>1</kd>
                  <max_vel>0.01</max_vel>
                  <min_depth>0</min_depth>
                </ode>
                <bullet>
                  <split_impulse>1</split_impulse>
                  <split_impulse_penetration_threshold>-0.01</split_impulse_penetration_threshold>
                  <soft_cfm>0</soft_cfm>
                  <soft_erp>0.2</soft_erp>
                  <kp>1e+13</kp>
                  <kd>1</kd>
                </bullet>
              </contact>
            </surface>
          </collision>
        </link>
        <link name='omni_wheel_roller_ne_link'>
          <pose frame=''>0.0055 0.009581 0.009581 0.875398 -0 0</pose>
          <inertial>
            <mass>0.00113845</mass>
            <inertia>
              <ixx>2.53776e-08</ixx>
              <ixy>0</ixy>
              <ixz>0</ixz>
              <iyy>2.53776e-08</iyy>
              <iyz>0</iyz>
              <izz>1.47666e-08</izz>
            </inertia>
            <pose frame=''>0 0 0 0 -0 0</pose>
          </inertial>
          <self_collide>0</self_collide>
          <kinematic>0</kinematic>
          <visual name='visual'>
            <pose frame=''>0 0 0 0 -0 0</pose>
            <geometry>
              <mesh>
                <uri>/home/minhhud/.gazebo/models/omni_wheel/roller.stl</uri>
              </mesh>
            </geometry>
            <material>
              <lighting>1</lighting>
              <script>
                <name>Gazebo/Grey</name>
                <uri>__default__</uri>
              </script>
              <ambient>0.03 0.03 0.03 1</ambient>
              <diffuse>0.07 0.07 0.07 1</diffuse>
              <specular>0.001 0.001 0.001 1</specular>
              <emissive>0 0 0 1</emissive>
              <shader type='vertex'>
                <normal_map>__default__</normal_map>
              </shader>
            </material>
            <transparency>0</transparency>
            <cast_shadows>1</cast_shadows>
          </visual>
          <collision name='collision'>
            <laser_retro>0</laser_retro>
            <max_contacts>10</max_contacts>
            <pose frame=''>0 0 0 0 -0 0</pose>
            <geometry>
              <mesh>
                <uri>/home/minhhud/.gazebo/models/omni_wheel/roller.stl</uri>
                <scale>1 1 1</scale>
              </mesh>
            </geometry>
            <surface>
              <friction>
                <ode>
                  <mu>1</mu>
                  <mu2>1</mu2>
                  <fdir1>0 0 0</fdir1>
                  <slip1>0</slip1>
                  <slip2>0</slip2>
                </ode>
                <torsional>
                  <coefficient>1</coefficient>
                  <patch_radius>0</patch_radius>
                  <surface_radius>0</surface_radius>
                  <use_patch_radius>1</use_patch_radius>
                  <ode>
                    <slip>0</slip>
                  </ode>
                </torsional>
              </friction>
              <bounce>
                <restitution_coefficient>0</restitution_coefficient>
                <threshold>1e+06</threshold>
              </bounce>
              <contact>
                <collide_without_contact>0</collide_without_contact>
                <collide_without_contact_bitmask>1</collide_without_contact_bitmask>
                <collide_bitmask>1</collide_bitmask>
                <ode>
                  <soft_cfm>0</soft_cfm>
                  <soft_erp>0.2</soft_erp>
                  <kp>1e+13</kp>
                  <kd>1</kd>
                  <max_vel>0.01</max_vel>
                  <min_depth>0</min_depth>
                </ode>
                <bullet>
                  <split_impulse>1</split_impulse>
                  <split_impulse_penetration_threshold>-0.01</split_impulse_penetration_threshold>
                  <soft_cfm>0</soft_cfm>
                  <soft_erp>0.2</soft_erp>
                  <kp>1e+13</kp>
                  <kd>1</kd>
                </bullet>
              </contact>
            </surface>
          </collision>
        </link>
        <link name='omni_wheel_roller_n_link'>
          <pose frame=''>-0.0055 0 0.01355 1.5708 -0 0</pose>
          <inertial>
            <mass>0.00113845</mass>
            <inertia>
              <ixx>2.53776e-08</ixx>
              <ixy>0</ixy>
              <ixz>0</ixz>
              <iyy>2.53776e-08</iyy>
              <iyz>0</iyz>
              <izz>1.47666e-08</izz>
            </inertia>
            <pose frame=''>0 0 0 0 -0 0</pose>
          </inertial>
          <self_collide>0</self_collide>
          <kinematic>0</kinematic>
          <gravity>1</gravity>
          <visual name='visual'>
            <pose frame=''>0 0 0 0 -0 0</pose>
            <geometry>
              <mesh>
                <uri>/home/minhhud/.gazebo/models/omni_wheel/roller.stl</uri>
                <scale>1 1 1</scale>
              </mesh>
            </geometry>
            <material>
              <lighting>1</lighting>
              <script>
                <name>Gazebo/Grey</name>
                <uri>__default__</uri>
              </script>
              <ambient>0.03 0.03 0.03 1</ambient>
              <diffuse>0.07 0.07 0.07 1</diffuse>
              <specular>0.001 0.001 0.001 1</specular>
              <emissive>0 0 0 1</emissive>
              <shader type='vertex'>
                <normal_map>__default__</normal_map>
              </shader>
            </material>
            <transparency>0</transparency>
            <cast_shadows>1</cast_shadows>
          </visual>
          <collision name='collision'>
            <laser_retro>0</laser_retro>
            <max_contacts>10</max_contacts>
            <pose frame=''>0 0 0 0 -0 0</pose>
            <geometry>
              <mesh>
                <uri>/home/minhhud/.gazebo/models/omni_wheel/roller.stl</uri>
                <scale>1 1 1</scale>
              </mesh>
            </geometry>
            <surface>
              <friction>
                <ode>
                  <mu>1</mu>
                  <mu2>1</mu2>
                  <fdir1>0 0 0</fdir1>
                  <slip1>0</slip1>
                  <slip2>0</slip2>
                </ode>
                <torsional>
                  <coefficient>1</coefficient>
                  <patch_radius>0</patch_radius>
                  <surface_radius>0</surface_radius>
                  <use_patch_radius>1</use_patch_radius>
                  <ode>
                    <slip>0</slip>
                  </ode>
                </torsional>
              </friction>
              <bounce>
                <restitution_coefficient>0</restitution_coefficient>
                <threshold>1e+06</threshold>
              </bounce>
              <contact>
                <collide_without_contact>0</collide_without_contact>
                <collide_without_contact_bitmask>1</collide_without_contact_bitmask>
                <collide_bitmask>1</collide_bitmask>
                <ode>
                  <soft_cfm>0</soft_cfm>
                  <soft_erp>0.2</soft_erp>
                  <kp>1e+13</kp>
                  <kd>1</kd>
                  <max_vel>0.01</max_vel>
                  <min_depth>0</min_depth>
                </ode>
                <bullet>
                  <split_impulse>1</split_impulse>
                  <split_impulse_penetration_threshold>-0.01</split_impulse_penetration_threshold>
                  <soft_cfm>0</soft_cfm>
                  <soft_erp>0.2</soft_erp>
                  <kp>1e+13</kp>
                  <kd>1</kd>
                </bullet>
              </contact>
            </surface>
          </collision>
        </link>
        <link name='omni_wheel_roller_nw_link'>
          <pose frame=''>0.0055 -0.009581 0.009581 2.35619 -0 0</pose>
          <inertial>
            <mass>0.00113845</mass>
            <inertia>
              <ixx>2.53776e-08</ixx>
              <ixy>0</ixy>
              <ixz>0</ixz>
              <iyy>2.53776e-08</iyy>
              <iyz>0</iyz>
              <izz>1.47666e-08</izz>
            </inertia>
            <pose frame=''>0 0 0 0 -0 0</pose>
          </inertial>
          <self_collide>0</self_collide>
          <kinematic>0</kinematic>
          <gravity>1</gravity>
          <visual name='visual'>
            <pose frame=''>0 0 0 0 -0 0</pose>
            <geometry>
              <mesh>
                <uri>/home/minhhud/.gazebo/models/omni_wheel/roller.stl</uri>
              </mesh>
            </geometry>
            <material>
              <lighting>1</lighting>
              <script>
                <name>Gazebo/Grey</name>
                <uri>__default__</uri>
              </script>
              <ambient>0.03 0.03 0.03 1</ambient>
              <diffuse>0.07 0.07 0.07 1</diffuse>
              <specular>0.001 0.001 0.001 1</specular>
              <emissive>0 0 0 1</emissive>
              <shader type='vertex'>
                <normal_map>__default__</normal_map>
              </shader>
            </material>
            <transparency>0</transparency>
            <cast_shadows>1</cast_shadows>
          </visual>
          <collision name='collision'>
            <laser_retro>0</laser_retro>
            <max_contacts>10</max_contacts>
            <pose frame=''>0 0 0 0 -0 0</pose>
            <geometry>
              <mesh>
                <uri>/home/minhhud/.gazebo/models/omni_wheel/roller.stl</uri>
                <scale>1 1 1</scale>
              </mesh>
            </geometry>
            <surface>
              <friction>
                <ode>
                  <mu>1</mu>
                  <mu2>1</mu2>
                  <fdir1>0 0 0</fdir1>
                  <slip1>0</slip1>
                  <slip2>0</slip2>
                </ode>
                <torsional>
                  <coefficient>1</coefficient>
                  <patch_radius>0</patch_radius>
                  <surface_radius>0</surface_radius>
                  <use_patch_radius>1</use_patch_radius>
                  <ode>
                    <slip>0</slip>
                  </ode>
                </torsional>
              </friction>
              <bounce>
                <restitution_coefficient>0</restitution_coefficient>
                <threshold>1e+06</threshold>
              </bounce>
              <contact>
                <collide_without_contact>0</collide_without_contact>
                <collide_without_contact_bitmask>1</collide_without_contact_bitmask>
                <collide_bitmask>1</collide_bitmask>
                <ode>
                  <soft_cfm>0</soft_cfm>
                  <soft_erp>0.2</soft_erp>
                  <kp>1e+13</kp>
                  <kd>1</kd>
                  <max_vel>0.01</max_vel>
                  <min_depth>0</min_depth>
                </ode>
                <bullet>
                  <split_impulse>1</split_impulse>
                  <split_impulse_penetration_threshold>-0.01</split_impulse_penetration_threshold>
                  <soft_cfm>0</soft_cfm>
                  <soft_erp>0.2</soft_erp>
                  <kp>1e+13</kp>
                  <kd>1</kd>
                </bullet>
              </contact>
            </surface>
          </collision>
        </link>
        <link name='omni_wheel_roller_w_link'>
          <pose frame=''>-0.0055 -0.01355 0 -3.14159 0 0</pose>
          <inertial>
            <mass>0.00113845</mass>
            <inertia>
              <ixx>2.53776e-08</ixx>
              <ixy>0</ixy>
              <ixz>0</ixz>
              <iyy>2.53776e-08</iyy>
              <iyz>0</iyz>
              <izz>1.47666e-08</izz>
            </inertia>
            <pose frame=''>0 0 0 0 -0 0</pose>
          </inertial>
          <self_collide>0</self_collide>
          <kinematic>0</kinematic>
          <gravity>1</gravity>
          <visual name='visual'>
            <pose frame=''>0 0 0 0 -0 0</pose>
            <geometry>
              <mesh>
                <uri>/home/minhhud/.gazebo/models/omni_wheel/roller.stl</uri>
              </mesh>
            </geometry>
            <material>
              <lighting>1</lighting>
              <script>
                <name>Gazebo/Grey</name>
                <uri>__default__</uri>
              </script>
              <ambient>0.03 0.03 0.03 1</ambient>
              <diffuse>0.07 0.07 0.07 1</diffuse>
              <specular>0.001 0.001 0.001 1</specular>
              <emissive>0 0 0 1</emissive>
              <shader type='vertex'>
                <normal_map>__default__</normal_map>
              </shader>
            </material>
            <transparency>0</transparency>
            <cast_shadows>1</cast_shadows>
          </visual>
          <collision name='collision'>
            <laser_retro>0</laser_retro>
            <max_contacts>10</max_contacts>
            <pose frame=''>0 0 0 0 -0 0</pose>
            <geometry>
              <mesh>
                <uri>/home/minhhud/.gazebo/models/omni_wheel/roller.stl</uri>
                <scale>1 1 1</scale>
              </mesh>
            </geometry>
            <surface>
              <friction>
                <ode>
                  <mu>1</mu>
                  <mu2>1</mu2>
                  <fdir1>0 0 0</fdir1>
                  <slip1>0</slip1>
                  <slip2>0</slip2>
                </ode>
                <torsional>
                  <coefficient>1</coefficient>
                  <patch_radius>0</patch_radius>
                  <surface_radius>0</surface_radius>
                  <use_patch_radius>1</use_patch_radius>
                  <ode>
                    <slip>0</slip>
                  </ode>
                </torsional>
              </friction>
              <bounce>
                <restitution_coefficient>0</restitution_coefficient>
                <threshold>1e+06</threshold>
              </bounce>
              <contact>
                <collide_without_contact>0</collide_without_contact>
                <collide_without_contact_bitmask>1</collide_without_contact_bitmask>
                <collide_bitmask>1</collide_bitmask>
                <ode>
                  <soft_cfm>0</soft_cfm>
                  <soft_erp>0.2</soft_erp>
                  <kp>1e+13</kp>
                  <kd>1</kd>
                  <max_vel>0.01</max_vel>
                  <min_depth>0</min_depth>
                </ode>
                <bullet>
                  <split_impulse>1</split_impulse>
                  <split_impulse_penetration_threshold>-0.01</split_impulse_penetration_threshold>
                  <soft_cfm>0</soft_cfm>
                  <soft_erp>0.2</soft_erp>
                  <kp>1e+13</kp>
                  <kd>1</kd>
                </bullet>
              </contact>
            </surface>
          </collision>
        </link>
        <link name='omni_wheel_roller_sw_link'>
          <pose frame=''>0.0055 -0.009581 -0.009581 -2.35619 0 0</pose>
          <inertial>
            <mass>0.00113845</mass>
            <inertia>
              <ixx>2.53776e-08</ixx>
              <ixy>0</ixy>
              <ixz>0</ixz>
              <iyy>2.53776e-08</iyy>
              <iyz>0</iyz>
              <izz>1.47666e-08</izz>
            </inertia>
            <pose frame=''>0 0 0 0 -0 0</pose>
          </inertial>
          <self_collide>0</self_collide>
          <kinematic>0</kinematic>
          <gravity>1</gravity>
          <visual name='visual'>
            <pose frame=''>0 0 0 0 -0 0</pose>
            <geometry>
              <mesh>
                <uri>/home/minhhud/.gazebo/models/omni_wheel/roller.stl</uri>
                <scale>1 1 1</scale>
              </mesh>
            </geometry>
            <material>
              <lighting>1</lighting>
              <script>
                <name>Gazebo/Grey</name>
                <uri>__default__</uri>
              </script>
              <ambient>0.03 0.03 0.03 1</ambient>
              <diffuse>0.07 0.07 0.07 1</diffuse>
              <specular>0.001 0.001 0.001 1</specular>
              <emissive>0 0 0 1</emissive>
              <shader type='vertex'>
                <normal_map>__default__</normal_map>
              </shader>
            </material>
            <transparency>0</transparency>
            <cast_shadows>1</cast_shadows>
          </visual>
          <collision name='collision'>
            <laser_retro>0</laser_retro>
            <max_contacts>10</max_contacts>
            <pose frame=''>0 0 0 0 -0 0</pose>
            <geometry>
              <mesh>
                <uri>/home/minhhud/.gazebo/models/omni_wheel/roller.stl</uri>
                <scale>1 1 1</scale>
              </mesh>
            </geometry>
            <surface>
              <friction>
                <ode>
                  <mu>1</mu>
                  <mu2>1</mu2>
                  <fdir1>0 0 0</fdir1>
                  <slip1>0</slip1>
                  <slip2>0</slip2>
                </ode>
                <torsional>
                  <coefficient>1</coefficient>
                  <patch_radius>0</patch_radius>
                  <surface_radius>0</surface_radius>
                  <use_patch_radius>1</use_patch_radius>
                  <ode>
                    <slip>0</slip>
                  </ode>
                </torsional>
              </friction>
              <bounce>
                <restitution_coefficient>0</restitution_coefficient>
                <threshold>1e+06</threshold>
              </bounce>
              <contact>
                <collide_without_contact>0</collide_without_contact>
                <collide_without_contact_bitmask>1</collide_without_contact_bitmask>
                <collide_bitmask>1</collide_bitmask>
                <ode>
                  <soft_cfm>0</soft_cfm>
                  <soft_erp>0.2</soft_erp>
                  <kp>1e+13</kp>
                  <kd>1</kd>
                  <max_vel>0.01</max_vel>
                  <min_depth>0</min_depth>
                </ode>
                <bullet>
                  <split_impulse>1</split_impulse>
                  <split_impulse_penetration_threshold>-0.01</split_impulse_penetration_threshold>
                  <soft_cfm>0</soft_cfm>
                  <soft_erp>0.2</soft_erp>
                  <kp>1e+13</kp>
                  <kd>1</kd>
                </bullet>
              </contact>
            </surface>
          </collision>
        </link>
        <link name='omni_wheel_roller_s_link'>
          <pose frame=''>-0.0055 0 -0.01355 -1.5708 0 0</pose>
          <inertial>
            <mass>0.00113845</mass>
            <inertia>
              <ixx>2.53776e-08</ixx>
              <ixy>0</ixy>
              <ixz>0</ixz>
              <iyy>2.53776e-08</iyy>
              <iyz>0</iyz>
              <izz>1.47666e-08</izz>
            </inertia>
            <pose frame=''>0 0 0 0 -0 0</pose>
          </inertial>
          <self_collide>0</self_collide>
          <kinematic>0</kinematic>
          <gravity>1</gravity>
          <visual name='visual'>
            <pose frame=''>0 0 0 0 -0 0</pose>
            <geometry>
              <mesh>
                <uri>/home/minhhud/.gazebo/models/omni_wheel/roller.stl</uri>
              </mesh>
            </geometry>
            <material>
              <lighting>1</lighting>
              <script>
                <name>Gazebo/Grey</name>
                <uri>__default__</uri>
              </script>
              <ambient>0.03 0.03 0.03 1</ambient>
              <diffuse>0.07 0.07 0.07 1</diffuse>
              <specular>0.001 0.001 0.001 1</specular>
              <emissive>0 0 0 1</emissive>
              <shader type='vertex'>
                <normal_map>__default__</normal_map>
              </shader>
            </material>
            <transparency>0</transparency>
            <cast_shadows>1</cast_shadows>
          </visual>
          <collision name='collision'>
            <laser_retro>0</laser_retro>
            <max_contacts>10</max_contacts>
            <pose frame=''>0 0 0 0 -0 0</pose>
            <geometry>
              <mesh>
                <uri>/home/minhhud/.gazebo/models/omni_wheel/roller.stl</uri>
                <scale>1 1 1</scale>
              </mesh>
            </geometry>
            <surface>
              <friction>
                <ode>
                  <mu>1</mu>
                  <mu2>1</mu2>
                  <fdir1>0 0 0</fdir1>
                  <slip1>0</slip1>
                  <slip2>0</slip2>
                </ode>
                <torsional>
                  <coefficient>1</coefficient>
                  <patch_radius>0</patch_radius>
                  <surface_radius>0</surface_radius>
                  <use_patch_radius>1</use_patch_radius>
                  <ode>
                    <slip>0</slip>
                  </ode>
                </torsional>
              </friction>
              <bounce>
                <restitution_coefficient>0</restitution_coefficient>
                <threshold>1e+06</threshold>
              </bounce>
              <contact>
                <collide_without_contact>0</collide_without_contact>
                <collide_without_contact_bitmask>1</collide_without_contact_bitmask>
                <collide_bitmask>1</collide_bitmask>
                <ode>
                  <soft_cfm>0</soft_cfm>
                  <soft_erp>0.2</soft_erp>
                  <kp>1e+13</kp>
                  <kd>1</kd>
                  <max_vel>0.01</max_vel>
                  <min_depth>0</min_depth>
                </ode>
                <bullet>
                  <split_impulse>1</split_impulse>
                  <split_impulse_penetration_threshold>-0.01</split_impulse_penetration_threshold>
                  <soft_cfm>0</soft_cfm>
                  <soft_erp>0.2</soft_erp>
                  <kp>1e+13</kp>
                  <kd>1</kd>
                </bullet>
              </contact>
            </surface>
          </collision>
        </link>
        <link name='omni_wheel_roller_se_link'>
          <pose frame=''>0.0055 0.009581 -0.009581 -0.875398 0 0</pose>
          <inertial>
            <mass>0.00113845</mass>
            <inertia>
              <ixx>2.53776e-08</ixx>
              <ixy>0</ixy>
              <ixz>0</ixz>
              <iyy>2.53776e-08</iyy>
              <iyz>0</iyz>
              <izz>1.47666e-08</izz>
            </inertia>
            <pose frame=''>0 0 0 0 -0 0</pose>
          </inertial>
          <self_collide>0</self_collide>
          <kinematic>0</kinematic>
          <gravity>1</gravity>
          <visual name='visual'>
            <pose frame=''>0 0 0 0 -0 0</pose>
            <geometry>
              <mesh>
                <uri>/home/minhhud/.gazebo/models/omni_wheel/roller.stl</uri>
                <scale>1 1 1</scale>
              </mesh>
            </geometry>
            <material>
              <lighting>1</lighting>
              <script>
                <name>Gazebo/Grey</name>
                <uri>__default__</uri>
              </script>
              <ambient>0.03 0.03 0.03 1</ambient>
              <diffuse>0.07 0.07 0.07 1</diffuse>
              <specular>0.001 0.001 0.001 1</specular>
              <emissive>0 0 0 1</emissive>
              <shader type='vertex'>
                <normal_map>__default__</normal_map>
              </shader>
            </material>
            <transparency>0</transparency>
            <cast_shadows>1</cast_shadows>
          </visual>
          <collision name='collision'>
            <laser_retro>0</laser_retro>
            <max_contacts>10</max_contacts>
            <pose frame=''>0 0 0 0 -0 0</pose>
            <geometry>
              <mesh>
                <uri>/home/minhhud/.gazebo/models/omni_wheel/roller.stl</uri>
                <scale>1 1 1</scale>
              </mesh>
            </geometry>
            <surface>
              <friction>
                <ode>
                  <mu>1</mu>
                  <mu2>1</mu2>
                  <fdir1>0 0 0</fdir1>
                  <slip1>0</slip1>
                  <slip2>0</slip2>
                </ode>
                <torsional>
                  <coefficient>1</coefficient>
                  <patch_radius>0</patch_radius>
                  <surface_radius>0</surface_radius>
                  <use_patch_radius>1</use_patch_radius>
                  <ode>
                    <slip>0</slip>
                  </ode>
                </torsional>
              </friction>
              <bounce>
                <restitution_coefficient>0</restitution_coefficient>
                <threshold>1e+06</threshold>
              </bounce>
              <contact>
                <collide_without_contact>0</collide_without_contact>
                <collide_without_contact_bitmask>1</collide_without_contact_bitmask>
                <collide_bitmask>1</collide_bitmask>
                <ode>
                  <soft_cfm>0</soft_cfm>
                  <soft_erp>0.2</soft_erp>
                  <kp>1e+13</kp>
                  <kd>1</kd>
                  <max_vel>0.01</max_vel>
                  <min_depth>0</min_depth>
                </ode>
                <bullet>
                  <split_impulse>1</split_impulse>
                  <split_impulse_penetration_threshold>-0.01</split_impulse_penetration_threshold>
                  <soft_cfm>0</soft_cfm>
                  <soft_erp>0.2</soft_erp>
                  <kp>1e+13</kp>
                  <kd>1</kd>
                </bullet>
              </contact>
            </surface>
          </collision>
        </link>
        <joint name='omni_wheel_s_joint' type='revolute'>
          <parent>omni_wheel_rim_link</parent>
          <child>omni_wheel_roller_s_link</child>
          <pose frame=''>0 0 0 0 -0 1.5708</pose>
          <axis>
            <xyz>0 0 1</xyz>
            <use_parent_model_frame>0</use_parent_model_frame>
            <limit>
              <lower>-1.79769e+308</lower>
              <upper>1.79769e+308</upper>
              <effort>-1</effort>
              <velocity>-1</velocity>
            </limit>
            <dynamics>
              <spring_reference>0</spring_reference>
              <spring_stiffness>0</spring_stiffness>
              <damping>0</damping>
              <friction>0</friction>
            </dynamics>
          </axis>
          <physics>
            <ode>
              <limit>
                <cfm>0</cfm>
                <erp>0.2</erp>
              </limit>
              <suspension>
                <cfm>0</cfm>
                <erp>0.2</erp>
              </suspension>
            </ode>
          </physics>
        </joint>
        <joint name='omni_wheel_se_joint' type='revolute'>
          <parent>omni_wheel_rim_link</parent>
          <child>omni_wheel_roller_se_link</child>
          <pose frame=''>0 0 0 0 -0 1.5708</pose>
          <axis>
            <xyz>0 0 1</xyz>
            <use_parent_model_frame>0</use_parent_model_frame>
            <limit>
              <lower>-1.79769e+308</lower>
              <upper>1.79769e+308</upper>
              <effort>-1</effort>
              <velocity>-1</velocity>
            </limit>
            <dynamics>
              <spring_reference>0</spring_reference>
              <spring_stiffness>0</spring_stiffness>
              <damping>0</damping>
              <friction>0</friction>
            </dynamics>
          </axis>
          <physics>
            <ode>
              <limit>
                <cfm>0</cfm>
                <erp>0.2</erp>
              </limit>
              <suspension>
                <cfm>0</cfm>
                <erp>0.2</erp>
              </suspension>
            </ode>
          </physics>
        </joint>
        <joint name='omni_wheel_e_joint' type='revolute'>
          <parent>omni_wheel_rim_link</parent>
          <child>omni_wheel_roller_e_link</child>
          <pose frame=''>0 0 0 0 -0 1.5708</pose>
          <axis>
            <xyz>0 0 1</xyz>
            <use_parent_model_frame>0</use_parent_model_frame>
            <limit>
              <lower>-1.79769e+308</lower>
              <upper>1.79769e+308</upper>
              <effort>-1</effort>
              <velocity>-1</velocity>
            </limit>
            <dynamics>
              <spring_reference>0</spring_reference>
              <spring_stiffness>0</spring_stiffness>
              <damping>0</damping>
              <friction>0</friction>
            </dynamics>
          </axis>
          <physics>
            <ode>
              <limit>
                <cfm>0</cfm>
                <erp>0.2</erp>
              </limit>
              <suspension>
                <cfm>0</cfm>
                <erp>0.2</erp>
              </suspension>
            </ode>
          </physics>
        </joint>
        <joint name='omni_wheel_ne_joint' type='revolute'>
          <parent>omni_wheel_rim_link</parent>
          <child>omni_wheel_roller_ne_link</child>
          <pose frame=''>0 0 0 0 -0 1.5708</pose>
          <axis>
            <xyz>0 0 1</xyz>
            <use_parent_model_frame>0</use_parent_model_frame>
            <limit>
              <lower>-1.79769e+308</lower>
              <upper>1.79769e+308</upper>
              <effort>-1</effort>
              <velocity>-1</velocity>
            </limit>
            <dynamics>
              <spring_reference>0</spring_reference>
              <spring_stiffness>0</spring_stiffness>
              <damping>0</damping>
              <friction>0</friction>
            </dynamics>
          </axis>
          <physics>
            <ode>
              <limit>
                <cfm>0</cfm>
                <erp>0.2</erp>
              </limit>
              <suspension>
                <cfm>0</cfm>
                <erp>0.2</erp>
              </suspension>
            </ode>
          </physics>
        </joint>
        <joint name='omni_wheel_n_joint' type='revolute'>
          <parent>omni_wheel_rim_link</parent>
          <child>omni_wheel_roller_n_link</child>
          <pose frame=''>0 0 0 0 -0 1.5708</pose>
          <axis>
            <xyz>0 0 1</xyz>
            <use_parent_model_frame>0</use_parent_model_frame>
            <limit>
              <lower>-1.79769e+308</lower>
              <upper>1.79769e+308</upper>
              <effort>-1</effort>
              <velocity>-1</velocity>
            </limit>
            <dynamics>
              <spring_reference>0</spring_reference>
              <spring_stiffness>0</spring_stiffness>
              <damping>0</damping>
              <friction>0</friction>
            </dynamics>
          </axis>
          <physics>
            <ode>
              <limit>
                <cfm>0</cfm>
                <erp>0.2</erp>
              </limit>
              <suspension>
                <cfm>0</cfm>
                <erp>0.2</erp>
              </suspension>
            </ode>
          </physics>
        </joint>
        <joint name='omni_wheel_nw_joint' type='revolute'>
          <parent>omni_wheel_rim_link</parent>
          <child>omni_wheel_roller_nw_link</child>
          <pose frame=''>0 0 0 0 -0 1.5708</pose>
          <axis>
            <xyz>0 0 1</xyz>
            <use_parent_model_frame>0</use_parent_model_frame>
            <limit>
              <lower>-1.79769e+308</lower>
              <upper>1.79769e+308</upper>
              <effort>-1</effort>
              <velocity>-1</velocity>
            </limit>
            <dynamics>
              <spring_reference>0</spring_reference>
              <spring_stiffness>0</spring_stiffness>
              <damping>0</damping>
              <friction>0</friction>
            </dynamics>
          </axis>
          <physics>
            <ode>
              <limit>
                <cfm>0</cfm>
                <erp>0.2</erp>
              </limit>
              <suspension>
                <cfm>0</cfm>
                <erp>0.2</erp>
              </suspension>
            </ode>
          </physics>
        </joint>
        <joint name='omni_wheel_w_joint' type='revolute'>
          <parent>omni_wheel_rim_link</parent>
          <child>omni_wheel_roller_w_link</child>
          <pose frame=''>0 0 0 0 -0 1.5708</pose>
          <axis>
            <xyz>0 0 1</xyz>
            <use_parent_model_frame>0</use_parent_model_frame>
            <limit>
              <lower>-1.79769e+308</lower>
              <upper>1.79769e+308</upper>
              <effort>-1</effort>
              <velocity>-1</velocity>
            </limit>
            <dynamics>
              <spring_reference>0</spring_reference>
              <spring_stiffness>0</spring_stiffness>
              <damping>0</damping>
              <friction>0</friction>
            </dynamics>
          </axis>
          <physics>
            <ode>
              <limit>
                <cfm>0</cfm>
                <erp>0.2</erp>
              </limit>
              <suspension>
                <cfm>0</cfm>
                <erp>0.2</erp>
              </suspension>
            </ode>
          </physics>
        </joint>
        <joint name='omni_wheel_sw_joint' type='revolute'>
          <parent>omni_wheel_rim_link</parent>
          <child>omni_wheel_roller_sw_link</child>
          <pose frame=''>0 0 0 0 -0 1.5708</pose>
          <axis>
            <xyz>0 0 1</xyz>
            <use_parent_model_frame>0</use_parent_model_frame>
            <limit>
              <lower>-1.79769e+308</lower>
              <upper>1.79769e+308</upper>
              <effort>-1</effort>
              <velocity>-1</velocity>
            </limit>
            <dynamics>
              <spring_reference>0</spring_reference>
              <spring_stiffness>0</spring_stiffness>
              <damping>0</damping>
              <friction>0</friction>
            </dynamics>
          </axis>
          <physics>
            <ode>
              <limit>
                <cfm>0</cfm>
                <erp>0.2</erp>
              </limit>
              <suspension>
                <cfm>0</cfm>
                <erp>0.2</erp>
              </suspension>
            </ode>
          </physics>
        </joint>
        <static>0</static>
        <allow_auto_disable>1</allow_auto_disable>
        <pose frame=''>-0.001547 0.174632 0 0 -0 1.52507</pose>
      </model>
      <model name='omni_wheel_model_1'>
        <link name='omni_wheel_rim_link'>
          <pose frame=''>0 0 0 0 -0 0</pose>
          <inertial>
            <mass>0.00835758</mass>
            <inertia>
              <ixx>9.40333e-07</ixx>
              <ixy>0</ixy>
              <ixz>0</ixz>
              <iyy>6.63684e-07</iyy>
              <iyz>0</iyz>
              <izz>6.63684e-07</izz>
            </inertia>
            <pose frame=''>0 -0.000343 0 0 -0 0</pose>
          </inertial>
          <self_collide>0</self_collide>
          <kinematic>0</kinematic>
          <gravity>1</gravity>
          <visual name='visual'>
            <pose frame=''>0 0 0 0 -0 0</pose>
            <geometry>
              <mesh>
                <uri>/home/minhhud/.gazebo/models/omni_wheel/rim.stl</uri>
                <scale>1 1 1</scale>
              </mesh>
            </geometry>
            <material>
              <lighting>1</lighting>
              <script>
                <name>Gazebo/Grey</name>
                <uri>__default__</uri>
              </script>
              <ambient>0.3 0.3 0.3 1</ambient>
              <diffuse>0.7 0.7 0.7 1</diffuse>
              <specular>0.01 0.01 0.01 1</specular>
              <emissive>0 0 0 1</emissive>
              <shader type='vertex'>
                <normal_map>__default__</normal_map>
              </shader>
            </material>
            <transparency>0</transparency>
            <cast_shadows>1</cast_shadows>
          </visual>
          <collision name='collision'>
            <laser_retro>0</laser_retro>
            <max_contacts>10</max_contacts>
            <pose frame=''>0 0 0 0 -0 0</pose>
            <geometry>
              <mesh>
                <uri>/home/minhhud/.gazebo/models/omni_wheel/rim.stl</uri>
                <scale>1 1 1</scale>
              </mesh>
            </geometry>
            <surface>
              <friction>
                <ode>
                  <mu>1</mu>
                  <mu2>1</mu2>
                  <fdir1>0 0 0</fdir1>
                  <slip1>0</slip1>
                  <slip2>0</slip2>
                </ode>
                <torsional>
                  <coefficient>1</coefficient>
                  <patch_radius>0</patch_radius>
                  <surface_radius>0</surface_radius>
                  <use_patch_radius>1</use_patch_radius>
                  <ode>
                    <slip>0</slip>
                  </ode>
                </torsional>
              </friction>
              <bounce>
                <restitution_coefficient>0</restitution_coefficient>
                <threshold>1e+06</threshold>
              </bounce>
              <contact>
                <collide_without_contact>0</collide_without_contact>
                <collide_without_contact_bitmask>1</collide_without_contact_bitmask>
                <collide_bitmask>1</collide_bitmask>
                <ode>
                  <soft_cfm>0</soft_cfm>
                  <soft_erp>0.2</soft_erp>
                  <kp>1e+13</kp>
                  <kd>1</kd>
                  <max_vel>0.01</max_vel>
                  <min_depth>0</min_depth>
                </ode>
                <bullet>
                  <split_impulse>1</split_impulse>
                  <split_impulse_penetration_threshold>-0.01</split_impulse_penetration_threshold>
                  <soft_cfm>0</soft_cfm>
                  <soft_erp>0.2</soft_erp>
                  <kp>1e+13</kp>
                  <kd>1</kd>
                </bullet>
              </contact>
            </surface>
          </collision>
        </link>
        <link name='omni_wheel_roller_e_link'>
          <pose frame=''>-0.0055 0.01355 0 0 -0 0</pose>
          <inertial>
            <mass>0.00113845</mass>
            <inertia>
              <ixx>2.53776e-08</ixx>
              <ixy>0</ixy>
              <ixz>0</ixz>
              <iyy>2.53776e-08</iyy>
              <iyz>0</iyz>
              <izz>1.47666e-08</izz>
            </inertia>
            <pose frame=''>0 0 0 0 -0 0</pose>
          </inertial>
          <self_collide>0</self_collide>
          <kinematic>0</kinematic>
          <visual name='visual'>
            <pose frame=''>0 0 0 0 -0 0</pose>
            <geometry>
              <mesh>
                <uri>/home/minhhud/.gazebo/models/omni_wheel/roller.stl</uri>
              </mesh>
            </geometry>
            <material>
              <lighting>1</lighting>
              <script>
                <name>Gazebo/Grey</name>
                <uri>__default__</uri>
              </script>
              <ambient>0.03 0.03 0.03 1</ambient>
              <diffuse>0.07 0.07 0.07 1</diffuse>
              <specular>0.001 0.001 0.001 1</specular>
              <emissive>0 0 0 1</emissive>
              <shader type='vertex'>
                <normal_map>__default__</normal_map>
              </shader>
            </material>
            <transparency>0</transparency>
            <cast_shadows>1</cast_shadows>
          </visual>
          <collision name='collision'>
            <laser_retro>0</laser_retro>
            <max_contacts>10</max_contacts>
            <pose frame=''>0 0 0 0 -0 0</pose>
            <geometry>
              <mesh>
                <uri>/home/minhhud/.gazebo/models/omni_wheel/roller.stl</uri>
                <scale>1 1 1</scale>
              </mesh>
            </geometry>
            <surface>
              <friction>
                <ode>
                  <mu>1</mu>
                  <mu2>1</mu2>
                  <fdir1>0 0 0</fdir1>
                  <slip1>0</slip1>
                  <slip2>0</slip2>
                </ode>
                <torsional>
                  <coefficient>1</coefficient>
                  <patch_radius>0</patch_radius>
                  <surface_radius>0</surface_radius>
                  <use_patch_radius>1</use_patch_radius>
                  <ode>
                    <slip>0</slip>
                  </ode>
                </torsional>
              </friction>
              <bounce>
                <restitution_coefficient>0</restitution_coefficient>
                <threshold>1e+06</threshold>
              </bounce>
              <contact>
                <collide_without_contact>0</collide_without_contact>
                <collide_without_contact_bitmask>1</collide_without_contact_bitmask>
                <collide_bitmask>1</collide_bitmask>
                <ode>
                  <soft_cfm>0</soft_cfm>
                  <soft_erp>0.2</soft_erp>
                  <kp>1e+13</kp>
                  <kd>1</kd>
                  <max_vel>0.01</max_vel>
                  <min_depth>0</min_depth>
                </ode>
                <bullet>
                  <split_impulse>1</split_impulse>
                  <split_impulse_penetration_threshold>-0.01</split_impulse_penetration_threshold>
                  <soft_cfm>0</soft_cfm>
                  <soft_erp>0.2</soft_erp>
                  <kp>1e+13</kp>
                  <kd>1</kd>
                </bullet>
              </contact>
            </surface>
          </collision>
        </link>
        <link name='omni_wheel_roller_ne_link'>
          <pose frame=''>0.0055 0.009581 0.009581 0.875398 -0 0</pose>
          <inertial>
            <mass>0.00113845</mass>
            <inertia>
              <ixx>2.53776e-08</ixx>
              <ixy>0</ixy>
              <ixz>0</ixz>
              <iyy>2.53776e-08</iyy>
              <iyz>0</iyz>
              <izz>1.47666e-08</izz>
            </inertia>
            <pose frame=''>0 0 0 0 -0 0</pose>
          </inertial>
          <self_collide>0</self_collide>
          <kinematic>0</kinematic>
          <visual name='visual'>
            <pose frame=''>0 0 0 0 -0 0</pose>
            <geometry>
              <mesh>
                <uri>/home/minhhud/.gazebo/models/omni_wheel/roller.stl</uri>
              </mesh>
            </geometry>
            <material>
              <lighting>1</lighting>
              <script>
                <name>Gazebo/Grey</name>
                <uri>__default__</uri>
              </script>
              <ambient>0.03 0.03 0.03 1</ambient>
              <diffuse>0.07 0.07 0.07 1</diffuse>
              <specular>0.001 0.001 0.001 1</specular>
              <emissive>0 0 0 1</emissive>
              <shader type='vertex'>
                <normal_map>__default__</normal_map>
              </shader>
            </material>
            <transparency>0</transparency>
            <cast_shadows>1</cast_shadows>
          </visual>
          <collision name='collision'>
            <laser_retro>0</laser_retro>
            <max_contacts>10</max_contacts>
            <pose frame=''>0 0 0 0 -0 0</pose>
            <geometry>
              <mesh>
                <uri>/home/minhhud/.gazebo/models/omni_wheel/roller.stl</uri>
                <scale>1 1 1</scale>
              </mesh>
            </geometry>
            <surface>
              <friction>
                <ode>
                  <mu>1</mu>
                  <mu2>1</mu2>
                  <fdir1>0 0 0</fdir1>
                  <slip1>0</slip1>
                  <slip2>0</slip2>
                </ode>
                <torsional>
                  <coefficient>1</coefficient>
                  <patch_radius>0</patch_radius>
                  <surface_radius>0</surface_radius>
                  <use_patch_radius>1</use_patch_radius>
                  <ode>
                    <slip>0</slip>
                  </ode>
                </torsional>
              </friction>
              <bounce>
                <restitution_coefficient>0</restitution_coefficient>
                <threshold>1e+06</threshold>
              </bounce>
              <contact>
                <collide_without_contact>0</collide_without_contact>
                <collide_without_contact_bitmask>1</collide_without_contact_bitmask>
                <collide_bitmask>1</collide_bitmask>
                <ode>
                  <soft_cfm>0</soft_cfm>
                  <soft_erp>0.2</soft_erp>
                  <kp>1e+13</kp>
                  <kd>1</kd>
                  <max_vel>0.01</max_vel>
                  <min_depth>0</min_depth>
                </ode>
                <bullet>
                  <split_impulse>1</split_impulse>
                  <split_impulse_penetration_threshold>-0.01</split_impulse_penetration_threshold>
                  <soft_cfm>0</soft_cfm>
                  <soft_erp>0.2</soft_erp>
                  <kp>1e+13</kp>
                  <kd>1</kd>
                </bullet>
              </contact>
            </surface>
          </collision>
        </link>
        <link name='omni_wheel_roller_n_link'>
          <pose frame=''>-0.0055 0 0.01355 1.5708 -0 0</pose>
          <inertial>
            <mass>0.00113845</mass>
            <inertia>
              <ixx>2.53776e-08</ixx>
              <ixy>0</ixy>
              <ixz>0</ixz>
              <iyy>2.53776e-08</iyy>
              <iyz>0</iyz>
              <izz>1.47666e-08</izz>
            </inertia>
            <pose frame=''>0 0 0 0 -0 0</pose>
          </inertial>
          <self_collide>0</self_collide>
          <kinematic>0</kinematic>
          <gravity>1</gravity>
          <visual name='visual'>
            <pose frame=''>0 0 0 0 -0 0</pose>
            <geometry>
              <mesh>
                <uri>/home/minhhud/.gazebo/models/omni_wheel/roller.stl</uri>
                <scale>1 1 1</scale>
              </mesh>
            </geometry>
            <material>
              <lighting>1</lighting>
              <script>
                <name>Gazebo/Grey</name>
                <uri>__default__</uri>
              </script>
              <ambient>0.03 0.03 0.03 1</ambient>
              <diffuse>0.07 0.07 0.07 1</diffuse>
              <specular>0.001 0.001 0.001 1</specular>
              <emissive>0 0 0 1</emissive>
              <shader type='vertex'>
                <normal_map>__default__</normal_map>
              </shader>
            </material>
            <transparency>0</transparency>
            <cast_shadows>1</cast_shadows>
          </visual>
          <collision name='collision'>
            <laser_retro>0</laser_retro>
            <max_contacts>10</max_contacts>
            <pose frame=''>0 0 0 0 -0 0</pose>
            <geometry>
              <mesh>
                <uri>/home/minhhud/.gazebo/models/omni_wheel/roller.stl</uri>
                <scale>1 1 1</scale>
              </mesh>
            </geometry>
            <surface>
              <friction>
                <ode>
                  <mu>1</mu>
                  <mu2>1</mu2>
                  <fdir1>0 0 0</fdir1>
                  <slip1>0</slip1>
                  <slip2>0</slip2>
                </ode>
                <torsional>
                  <coefficient>1</coefficient>
                  <patch_radius>0</patch_radius>
                  <surface_radius>0</surface_radius>
                  <use_patch_radius>1</use_patch_radius>
                  <ode>
                    <slip>0</slip>
                  </ode>
                </torsional>
              </friction>
              <bounce>
                <restitution_coefficient>0</restitution_coefficient>
                <threshold>1e+06</threshold>
              </bounce>
              <contact>
                <collide_without_contact>0</collide_without_contact>
                <collide_without_contact_bitmask>1</collide_without_contact_bitmask>
                <collide_bitmask>1</collide_bitmask>
                <ode>
                  <soft_cfm>0</soft_cfm>
                  <soft_erp>0.2</soft_erp>
                  <kp>1e+13</kp>
                  <kd>1</kd>
                  <max_vel>0.01</max_vel>
                  <min_depth>0</min_depth>
                </ode>
                <bullet>
                  <split_impulse>1</split_impulse>
                  <split_impulse_penetration_threshold>-0.01</split_impulse_penetration_threshold>
                  <soft_cfm>0</soft_cfm>
                  <soft_erp>0.2</soft_erp>
                  <kp>1e+13</kp>
                  <kd>1</kd>
                </bullet>
              </contact>
            </surface>
          </collision>
        </link>
        <link name='omni_wheel_roller_nw_link'>
          <pose frame=''>0.0055 -0.009581 0.009581 2.35619 -0 0</pose>
          <inertial>
            <mass>0.00113845</mass>
            <inertia>
              <ixx>2.53776e-08</ixx>
              <ixy>0</ixy>
              <ixz>0</ixz>
              <iyy>2.53776e-08</iyy>
              <iyz>0</iyz>
              <izz>1.47666e-08</izz>
            </inertia>
            <pose frame=''>0 0 0 0 -0 0</pose>
          </inertial>
          <self_collide>0</self_collide>
          <kinematic>0</kinematic>
          <gravity>1</gravity>
          <visual name='visual'>
            <pose frame=''>0 0 0 0 -0 0</pose>
            <geometry>
              <mesh>
                <uri>/home/minhhud/.gazebo/models/omni_wheel/roller.stl</uri>
              </mesh>
            </geometry>
            <material>
              <lighting>1</lighting>
              <script>
                <name>Gazebo/Grey</name>
                <uri>__default__</uri>
              </script>
              <ambient>0.03 0.03 0.03 1</ambient>
              <diffuse>0.07 0.07 0.07 1</diffuse>
              <specular>0.001 0.001 0.001 1</specular>
              <emissive>0 0 0 1</emissive>
              <shader type='vertex'>
                <normal_map>__default__</normal_map>
              </shader>
            </material>
            <transparency>0</transparency>
            <cast_shadows>1</cast_shadows>
          </visual>
          <collision name='collision'>
            <laser_retro>0</laser_retro>
            <max_contacts>10</max_contacts>
            <pose frame=''>0 0 0 0 -0 0</pose>
            <geometry>
              <mesh>
                <uri>/home/minhhud/.gazebo/models/omni_wheel/roller.stl</uri>
                <scale>1 1 1</scale>
              </mesh>
            </geometry>
            <surface>
              <friction>
                <ode>
                  <mu>1</mu>
                  <mu2>1</mu2>
                  <fdir1>0 0 0</fdir1>
                  <slip1>0</slip1>
                  <slip2>0</slip2>
                </ode>
                <torsional>
                  <coefficient>1</coefficient>
                  <patch_radius>0</patch_radius>
                  <surface_radius>0</surface_radius>
                  <use_patch_radius>1</use_patch_radius>
                  <ode>
                    <slip>0</slip>
                  </ode>
                </torsional>
              </friction>
              <bounce>
                <restitution_coefficient>0</restitution_coefficient>
                <threshold>1e+06</threshold>
              </bounce>
              <contact>
                <collide_without_contact>0</collide_without_contact>
                <collide_without_contact_bitmask>1</collide_without_contact_bitmask>
                <collide_bitmask>1</collide_bitmask>
                <ode>
                  <soft_cfm>0</soft_cfm>
                  <soft_erp>0.2</soft_erp>
                  <kp>1e+13</kp>
                  <kd>1</kd>
                  <max_vel>0.01</max_vel>
                  <min_depth>0</min_depth>
                </ode>
                <bullet>
                  <split_impulse>1</split_impulse>
                  <split_impulse_penetration_threshold>-0.01</split_impulse_penetration_threshold>
                  <soft_cfm>0</soft_cfm>
                  <soft_erp>0.2</soft_erp>
                  <kp>1e+13</kp>
                  <kd>1</kd>
                </bullet>
              </contact>
            </surface>
          </collision>
        </link>
        <link name='omni_wheel_roller_w_link'>
          <pose frame=''>-0.0055 -0.01355 0 -3.14159 0 0</pose>
          <inertial>
            <mass>0.00113845</mass>
            <inertia>
              <ixx>2.53776e-08</ixx>
              <ixy>0</ixy>
              <ixz>0</ixz>
              <iyy>2.53776e-08</iyy>
              <iyz>0</iyz>
              <izz>1.47666e-08</izz>
            </inertia>
            <pose frame=''>0 0 0 0 -0 0</pose>
          </inertial>
          <self_collide>0</self_collide>
          <kinematic>0</kinematic>
          <gravity>1</gravity>
          <visual name='visual'>
            <pose frame=''>0 0 0 0 -0 0</pose>
            <geometry>
              <mesh>
                <uri>/home/minhhud/.gazebo/models/omni_wheel/roller.stl</uri>
              </mesh>
            </geometry>
            <material>
              <lighting>1</lighting>
              <script>
                <name>Gazebo/Grey</name>
                <uri>__default__</uri>
              </script>
              <ambient>0.03 0.03 0.03 1</ambient>
              <diffuse>0.07 0.07 0.07 1</diffuse>
              <specular>0.001 0.001 0.001 1</specular>
              <emissive>0 0 0 1</emissive>
              <shader type='vertex'>
                <normal_map>__default__</normal_map>
              </shader>
            </material>
            <transparency>0</transparency>
            <cast_shadows>1</cast_shadows>
          </visual>
          <collision name='collision'>
            <laser_retro>0</laser_retro>
            <max_contacts>10</max_contacts>
            <pose frame=''>0 0 0 0 -0 0</pose>
            <geometry>
              <mesh>
                <uri>/home/minhhud/.gazebo/models/omni_wheel/roller.stl</uri>
                <scale>1 1 1</scale>
              </mesh>
            </geometry>
            <surface>
              <friction>
                <ode>
                  <mu>1</mu>
                  <mu2>1</mu2>
                  <fdir1>0 0 0</fdir1>
                  <slip1>0</slip1>
                  <slip2>0</slip2>
                </ode>
                <torsional>
                  <coefficient>1</coefficient>
                  <patch_radius>0</patch_radius>
                  <surface_radius>0</surface_radius>
                  <use_patch_radius>1</use_patch_radius>
                  <ode>
                    <slip>0</slip>
                  </ode>
                </torsional>
              </friction>
              <bounce>
                <restitution_coefficient>0</restitution_coefficient>
                <threshold>1e+06</threshold>
              </bounce>
              <contact>
                <collide_without_contact>0</collide_without_contact>
                <collide_without_contact_bitmask>1</collide_without_contact_bitmask>
                <collide_bitmask>1</collide_bitmask>
                <ode>
                  <soft_cfm>0</soft_cfm>
                  <soft_erp>0.2</soft_erp>
                  <kp>1e+13</kp>
                  <kd>1</kd>
                  <max_vel>0.01</max_vel>
                  <min_depth>0</min_depth>
                </ode>
                <bullet>
                  <split_impulse>1</split_impulse>
                  <split_impulse_penetration_threshold>-0.01</split_impulse_penetration_threshold>
                  <soft_cfm>0</soft_cfm>
                  <soft_erp>0.2</soft_erp>
                  <kp>1e+13</kp>
                  <kd>1</kd>
                </bullet>
              </contact>
            </surface>
          </collision>
        </link>
        <link name='omni_wheel_roller_sw_link'>
          <pose frame=''>0.0055 -0.009581 -0.009581 -2.35619 0 0</pose>
          <inertial>
            <mass>0.00113845</mass>
            <inertia>
              <ixx>2.53776e-08</ixx>
              <ixy>0</ixy>
              <ixz>0</ixz>
              <iyy>2.53776e-08</iyy>
              <iyz>0</iyz>
              <izz>1.47666e-08</izz>
            </inertia>
            <pose frame=''>0 0 0 0 -0 0</pose>
          </inertial>
          <self_collide>0</self_collide>
          <kinematic>0</kinematic>
          <gravity>1</gravity>
          <visual name='visual'>
            <pose frame=''>0 0 0 0 -0 0</pose>
            <geometry>
              <mesh>
                <uri>/home/minhhud/.gazebo/models/omni_wheel/roller.stl</uri>
                <scale>1 1 1</scale>
              </mesh>
            </geometry>
            <material>
              <lighting>1</lighting>
              <script>
                <name>Gazebo/Grey</name>
                <uri>__default__</uri>
              </script>
              <ambient>0.03 0.03 0.03 1</ambient>
              <diffuse>0.07 0.07 0.07 1</diffuse>
              <specular>0.001 0.001 0.001 1</specular>
              <emissive>0 0 0 1</emissive>
              <shader type='vertex'>
                <normal_map>__default__</normal_map>
              </shader>
            </material>
            <transparency>0</transparency>
            <cast_shadows>1</cast_shadows>
          </visual>
          <collision name='collision'>
            <laser_retro>0</laser_retro>
            <max_contacts>10</max_contacts>
            <pose frame=''>0 0 0 0 -0 0</pose>
            <geometry>
              <mesh>
                <uri>/home/minhhud/.gazebo/models/omni_wheel/roller.stl</uri>
                <scale>1 1 1</scale>
              </mesh>
            </geometry>
            <surface>
              <friction>
                <ode>
                  <mu>1</mu>
                  <mu2>1</mu2>
                  <fdir1>0 0 0</fdir1>
                  <slip1>0</slip1>
                  <slip2>0</slip2>
                </ode>
                <torsional>
                  <coefficient>1</coefficient>
                  <patch_radius>0</patch_radius>
                  <surface_radius>0</surface_radius>
                  <use_patch_radius>1</use_patch_radius>
                  <ode>
                    <slip>0</slip>
                  </ode>
                </torsional>
              </friction>
              <bounce>
                <restitution_coefficient>0</restitution_coefficient>
                <threshold>1e+06</threshold>
              </bounce>
              <contact>
                <collide_without_contact>0</collide_without_contact>
                <collide_without_contact_bitmask>1</collide_without_contact_bitmask>
                <collide_bitmask>1</collide_bitmask>
                <ode>
                  <soft_cfm>0</soft_cfm>
                  <soft_erp>0.2</soft_erp>
                  <kp>1e+13</kp>
                  <kd>1</kd>
                  <max_vel>0.01</max_vel>
                  <min_depth>0</min_depth>
                </ode>
                <bullet>
                  <split_impulse>1</split_impulse>
                  <split_impulse_penetration_threshold>-0.01</split_impulse_penetration_threshold>
                  <soft_cfm>0</soft_cfm>
                  <soft_erp>0.2</soft_erp>
                  <kp>1e+13</kp>
                  <kd>1</kd>
                </bullet>
              </contact>
            </surface>
          </collision>
        </link>
        <link name='omni_wheel_roller_s_link'>
          <pose frame=''>-0.0055 0 -0.01355 -1.5708 0 0</pose>
          <inertial>
            <mass>0.00113845</mass>
            <inertia>
              <ixx>2.53776e-08</ixx>
              <ixy>0</ixy>
              <ixz>0</ixz>
              <iyy>2.53776e-08</iyy>
              <iyz>0</iyz>
              <izz>1.47666e-08</izz>
            </inertia>
            <pose frame=''>0 0 0 0 -0 0</pose>
          </inertial>
          <self_collide>0</self_collide>
          <kinematic>0</kinematic>
          <gravity>1</gravity>
          <visual name='visual'>
            <pose frame=''>0 0 0 0 -0 0</pose>
            <geometry>
              <mesh>
                <uri>/home/minhhud/.gazebo/models/omni_wheel/roller.stl</uri>
              </mesh>
            </geometry>
            <material>
              <lighting>1</lighting>
              <script>
                <name>Gazebo/Grey</name>
                <uri>__default__</uri>
              </script>
              <ambient>0.03 0.03 0.03 1</ambient>
              <diffuse>0.07 0.07 0.07 1</diffuse>
              <specular>0.001 0.001 0.001 1</specular>
              <emissive>0 0 0 1</emissive>
              <shader type='vertex'>
                <normal_map>__default__</normal_map>
              </shader>
            </material>
            <transparency>0</transparency>
            <cast_shadows>1</cast_shadows>
          </visual>
          <collision name='collision'>
            <laser_retro>0</laser_retro>
            <max_contacts>10</max_contacts>
            <pose frame=''>0 0 0 0 -0 0</pose>
            <geometry>
              <mesh>
                <uri>/home/minhhud/.gazebo/models/omni_wheel/roller.stl</uri>
                <scale>1 1 1</scale>
              </mesh>
            </geometry>
            <surface>
              <friction>
                <ode>
                  <mu>1</mu>
                  <mu2>1</mu2>
                  <fdir1>0 0 0</fdir1>
                  <slip1>0</slip1>
                  <slip2>0</slip2>
                </ode>
                <torsional>
                  <coefficient>1</coefficient>
                  <patch_radius>0</patch_radius>
                  <surface_radius>0</surface_radius>
                  <use_patch_radius>1</use_patch_radius>
                  <ode>
                    <slip>0</slip>
                  </ode>
                </torsional>
              </friction>
              <bounce>
                <restitution_coefficient>0</restitution_coefficient>
                <threshold>1e+06</threshold>
              </bounce>
              <contact>
                <collide_without_contact>0</collide_without_contact>
                <collide_without_contact_bitmask>1</collide_without_contact_bitmask>
                <collide_bitmask>1</collide_bitmask>
                <ode>
                  <soft_cfm>0</soft_cfm>
                  <soft_erp>0.2</soft_erp>
                  <kp>1e+13</kp>
                  <kd>1</kd>
                  <max_vel>0.01</max_vel>
                  <min_depth>0</min_depth>
                </ode>
                <bullet>
                  <split_impulse>1</split_impulse>
                  <split_impulse_penetration_threshold>-0.01</split_impulse_penetration_threshold>
                  <soft_cfm>0</soft_cfm>
                  <soft_erp>0.2</soft_erp>
                  <kp>1e+13</kp>
                  <kd>1</kd>
                </bullet>
              </contact>
            </surface>
          </collision>
        </link>
        <link name='omni_wheel_roller_se_link'>
          <pose frame=''>0.0055 0.009581 -0.009581 -0.875398 0 0</pose>
          <inertial>
            <mass>0.00113845</mass>
            <inertia>
              <ixx>2.53776e-08</ixx>
              <ixy>0</ixy>
              <ixz>0</ixz>
              <iyy>2.53776e-08</iyy>
              <iyz>0</iyz>
              <izz>1.47666e-08</izz>
            </inertia>
            <pose frame=''>0 0 0 0 -0 0</pose>
          </inertial>
          <self_collide>0</self_collide>
          <kinematic>0</kinematic>
          <gravity>1</gravity>
          <visual name='visual'>
            <pose frame=''>0 0 0 0 -0 0</pose>
            <geometry>
              <mesh>
                <uri>/home/minhhud/.gazebo/models/omni_wheel/roller.stl</uri>
                <scale>1 1 1</scale>
              </mesh>
            </geometry>
            <material>
              <lighting>1</lighting>
              <script>
                <name>Gazebo/Grey</name>
                <uri>__default__</uri>
              </script>
              <ambient>0.03 0.03 0.03 1</ambient>
              <diffuse>0.07 0.07 0.07 1</diffuse>
              <specular>0.001 0.001 0.001 1</specular>
              <emissive>0 0 0 1</emissive>
              <shader type='vertex'>
                <normal_map>__default__</normal_map>
              </shader>
            </material>
            <transparency>0</transparency>
            <cast_shadows>1</cast_shadows>
          </visual>
          <collision name='collision'>
            <laser_retro>0</laser_retro>
            <max_contacts>10</max_contacts>
            <pose frame=''>0 0 0 0 -0 0</pose>
            <geometry>
              <mesh>
                <uri>/home/minhhud/.gazebo/models/omni_wheel/roller.stl</uri>
                <scale>1 1 1</scale>
              </mesh>
            </geometry>
            <surface>
              <friction>
                <ode>
                  <mu>1</mu>
                  <mu2>1</mu2>
                  <fdir1>0 0 0</fdir1>
                  <slip1>0</slip1>
                  <slip2>0</slip2>
                </ode>
                <torsional>
                  <coefficient>1</coefficient>
                  <patch_radius>0</patch_radius>
                  <surface_radius>0</surface_radius>
                  <use_patch_radius>1</use_patch_radius>
                  <ode>
                    <slip>0</slip>
                  </ode>
                </torsional>
              </friction>
              <bounce>
                <restitution_coefficient>0</restitution_coefficient>
                <threshold>1e+06</threshold>
              </bounce>
              <contact>
                <collide_without_contact>0</collide_without_contact>
                <collide_without_contact_bitmask>1</collide_without_contact_bitmask>
                <collide_bitmask>1</collide_bitmask>
                <ode>
                  <soft_cfm>0</soft_cfm>
                  <soft_erp>0.2</soft_erp>
                  <kp>1e+13</kp>
                  <kd>1</kd>
                  <max_vel>0.01</max_vel>
                  <min_depth>0</min_depth>
                </ode>
                <bullet>
                  <split_impulse>1</split_impulse>
                  <split_impulse_penetration_threshold>-0.01</split_impulse_penetration_threshold>
                  <soft_cfm>0</soft_cfm>
                  <soft_erp>0.2</soft_erp>
                  <kp>1e+13</kp>
                  <kd>1</kd>
                </bullet>
              </contact>
            </surface>
          </collision>
        </link>
        <joint name='omni_wheel_s_joint' type='revolute'>
          <parent>omni_wheel_rim_link</parent>
          <child>omni_wheel_roller_s_link</child>
          <pose frame=''>0 0 0 0 -0 1.5708</pose>
          <axis>
            <xyz>0 0 1</xyz>
            <use_parent_model_frame>0</use_parent_model_frame>
            <limit>
              <lower>-1.79769e+308</lower>
              <upper>1.79769e+308</upper>
              <effort>-1</effort>
              <velocity>-1</velocity>
            </limit>
            <dynamics>
              <spring_reference>0</spring_reference>
              <spring_stiffness>0</spring_stiffness>
              <damping>0</damping>
              <friction>0</friction>
            </dynamics>
          </axis>
          <physics>
            <ode>
              <limit>
                <cfm>0</cfm>
                <erp>0.2</erp>
              </limit>
              <suspension>
                <cfm>0</cfm>
                <erp>0.2</erp>
              </suspension>
            </ode>
          </physics>
        </joint>
        <joint name='omni_wheel_se_joint' type='revolute'>
          <parent>omni_wheel_rim_link</parent>
          <child>omni_wheel_roller_se_link</child>
          <pose frame=''>0 0 0 0 -0 1.5708</pose>
          <axis>
            <xyz>0 0 1</xyz>
            <use_parent_model_frame>0</use_parent_model_frame>
            <limit>
              <lower>-1.79769e+308</lower>
              <upper>1.79769e+308</upper>
              <effort>-1</effort>
              <velocity>-1</velocity>
            </limit>
            <dynamics>
              <spring_reference>0</spring_reference>
              <spring_stiffness>0</spring_stiffness>
              <damping>0</damping>
              <friction>0</friction>
            </dynamics>
          </axis>
          <physics>
            <ode>
              <limit>
                <cfm>0</cfm>
                <erp>0.2</erp>
              </limit>
              <suspension>
                <cfm>0</cfm>
                <erp>0.2</erp>
              </suspension>
            </ode>
          </physics>
        </joint>
        <joint name='omni_wheel_e_joint' type='revolute'>
          <parent>omni_wheel_rim_link</parent>
          <child>omni_wheel_roller_e_link</child>
          <pose frame=''>0 0 0 0 -0 1.5708</pose>
          <axis>
            <xyz>0 0 1</xyz>
            <use_parent_model_frame>0</use_parent_model_frame>
            <limit>
              <lower>-1.79769e+308</lower>
              <upper>1.79769e+308</upper>
              <effort>-1</effort>
              <velocity>-1</velocity>
            </limit>
            <dynamics>
              <spring_reference>0</spring_reference>
              <spring_stiffness>0</spring_stiffness>
              <damping>0</damping>
              <friction>0</friction>
            </dynamics>
          </axis>
          <physics>
            <ode>
              <limit>
                <cfm>0</cfm>
                <erp>0.2</erp>
              </limit>
              <suspension>
                <cfm>0</cfm>
                <erp>0.2</erp>
              </suspension>
            </ode>
          </physics>
        </joint>
        <joint name='omni_wheel_ne_joint' type='revolute'>
          <parent>omni_wheel_rim_link</parent>
          <child>omni_wheel_roller_ne_link</child>
          <pose frame=''>0 0 0 0 -0 1.5708</pose>
          <axis>
            <xyz>0 0 1</xyz>
            <use_parent_model_frame>0</use_parent_model_frame>
            <limit>
              <lower>-1.79769e+308</lower>
              <upper>1.79769e+308</upper>
              <effort>-1</effort>
              <velocity>-1</velocity>
            </limit>
            <dynamics>
              <spring_reference>0</spring_reference>
              <spring_stiffness>0</spring_stiffness>
              <damping>0</damping>
              <friction>0</friction>
            </dynamics>
          </axis>
          <physics>
            <ode>
              <limit>
                <cfm>0</cfm>
                <erp>0.2</erp>
              </limit>
              <suspension>
                <cfm>0</cfm>
                <erp>0.2</erp>
              </suspension>
            </ode>
          </physics>
        </joint>
        <joint name='omni_wheel_n_joint' type='revolute'>
          <parent>omni_wheel_rim_link</parent>
          <child>omni_wheel_roller_n_link</child>
          <pose frame=''>0 0 0 0 -0 1.5708</pose>
          <axis>
            <xyz>0 0 1</xyz>
            <use_parent_model_frame>0</use_parent_model_frame>
            <limit>
              <lower>-1.79769e+308</lower>
              <upper>1.79769e+308</upper>
              <effort>-1</effort>
              <velocity>-1</velocity>
            </limit>
            <dynamics>
              <spring_reference>0</spring_reference>
              <spring_stiffness>0</spring_stiffness>
              <damping>0</damping>
              <friction>0</friction>
            </dynamics>
          </axis>
          <physics>
            <ode>
              <limit>
                <cfm>0</cfm>
                <erp>0.2</erp>
              </limit>
              <suspension>
                <cfm>0</cfm>
                <erp>0.2</erp>
              </suspension>
            </ode>
          </physics>
        </joint>
        <joint name='omni_wheel_nw_joint' type='revolute'>
          <parent>omni_wheel_rim_link</parent>
          <child>omni_wheel_roller_nw_link</child>
          <pose frame=''>0 0 0 0 -0 1.5708</pose>
          <axis>
            <xyz>0 0 1</xyz>
            <use_parent_model_frame>0</use_parent_model_frame>
            <limit>
              <lower>-1.79769e+308</lower>
              <upper>1.79769e+308</upper>
              <effort>-1</effort>
              <velocity>-1</velocity>
            </limit>
            <dynamics>
              <spring_reference>0</spring_reference>
              <spring_stiffness>0</spring_stiffness>
              <damping>0</damping>
              <friction>0</friction>
            </dynamics>
          </axis>
          <physics>
            <ode>
              <limit>
                <cfm>0</cfm>
                <erp>0.2</erp>
              </limit>
              <suspension>
                <cfm>0</cfm>
                <erp>0.2</erp>
              </suspension>
            </ode>
          </physics>
        </joint>
        <joint name='omni_wheel_w_joint' type='revolute'>
          <parent>omni_wheel_rim_link</parent>
          <child>omni_wheel_roller_w_link</child>
          <pose frame=''>0 0 0 0 -0 1.5708</pose>
          <axis>
            <xyz>0 0 1</xyz>
            <use_parent_model_frame>0</use_parent_model_frame>
            <limit>
              <lower>-1.79769e+308</lower>
              <upper>1.79769e+308</upper>
              <effort>-1</effort>
              <velocity>-1</velocity>
            </limit>
            <dynamics>
              <spring_reference>0</spring_reference>
              <spring_stiffness>0</spring_stiffness>
              <damping>0</damping>
              <friction>0</friction>
            </dynamics>
          </axis>
          <physics>
            <ode>
              <limit>
                <cfm>0</cfm>
                <erp>0.2</erp>
              </limit>
              <suspension>
                <cfm>0</cfm>
                <erp>0.2</erp>
              </suspension>
            </ode>
          </physics>
        </joint>
        <joint name='omni_wheel_sw_joint' type='revolute'>
          <parent>omni_wheel_rim_link</parent>
          <child>omni_wheel_roller_sw_link</child>
          <pose frame=''>0 0 0 0 -0 1.5708</pose>
          <axis>
            <xyz>0 0 1</xyz>
            <use_parent_model_frame>0</use_parent_model_frame>
            <limit>
              <lower>-1.79769e+308</lower>
              <upper>1.79769e+308</upper>
              <effort>-1</effort>
              <velocity>-1</velocity>
            </limit>
            <dynamics>
              <spring_reference>0</spring_reference>
              <spring_stiffness>0</spring_stiffness>
              <damping>0</damping>
              <friction>0</friction>
            </dynamics>
          </axis>
          <physics>
            <ode>
              <limit>
                <cfm>0</cfm>
                <erp>0.2</erp>
              </limit>
              <suspension>
                <cfm>0</cfm>
                <erp>0.2</erp>
              </suspension>
            </ode>
          </physics>
        </joint>
        <static>0</static>
        <allow_auto_disable>1</allow_auto_disable>
        <pose frame=''>0.152263 -0.085749 0 0 0 -0.499135</pose>
      </model>
      <joint name='link_1_JOINT' type='revolute'>
        <parent>link_1</parent>
        <child>omni_wheel_model::omni_wheel_rim_link</child>
        <pose frame=''>0 0 0 3.14159 -1.57079 3.14159</pose>
        <axis>
          <xyz>0 0 1</xyz>
          <use_parent_model_frame>0</use_parent_model_frame>
          <limit>
            <lower>-1.79769e+308</lower>
            <upper>1.79769e+308</upper>
            <effort>-1</effort>
            <velocity>-1</velocity>
          </limit>
          <dynamics>
            <spring_reference>0</spring_reference>
            <spring_stiffness>0</spring_stiffness>
            <damping>0</damping>
            <friction>0</friction>
          </dynamics>
        </axis>
        <physics>
          <ode>
            <limit>
              <cfm>0</cfm>
              <erp>0.2</erp>
            </limit>
            <suspension>
              <cfm>0</cfm>
              <erp>0.2</erp>
            </suspension>
          </ode>
        </physics>
      </joint>
      <joint name='link_1_JOINT_0' type='revolute'>
        <parent>link_1</parent>
        <child>omni_wheel_model_0::omni_wheel_rim_link</child>
        <pose frame=''>0 0 0 3.14159 -1.57079 3.14159</pose>
        <axis>
          <xyz>0 0 1</xyz>
          <use_parent_model_frame>0</use_parent_model_frame>
          <limit>
            <lower>-1.79769e+308</lower>
            <upper>1.79769e+308</upper>
            <effort>-1</effort>
            <velocity>-1</velocity>
          </limit>
          <dynamics>
            <spring_reference>0</spring_reference>
            <spring_stiffness>0</spring_stiffness>
            <damping>0</damping>
            <friction>0</friction>
          </dynamics>
        </axis>
        <physics>
          <ode>
            <limit>
              <cfm>0</cfm>
              <erp>0.2</erp>
            </limit>
            <suspension>
              <cfm>0</cfm>
              <erp>0.2</erp>
            </suspension>
          </ode>
        </physics>
      </joint>
      <joint name='link_1_JOINT_1' type='revolute'>
        <parent>link_1</parent>
        <child>omni_wheel_model_1::omni_wheel_rim_link</child>
        <pose frame=''>0 0 0 3.14159 -1.57079 3.14159</pose>
        <axis>
          <xyz>0 0 1</xyz>
          <use_parent_model_frame>0</use_parent_model_frame>
          <limit>
            <lower>-1.79769e+308</lower>
            <upper>1.79769e+308</upper>
            <effort>-1</effort>
            <velocity>-1</velocity>
          </limit>
          <dynamics>
            <spring_reference>0</spring_reference>
            <spring_stiffness>0</spring_stiffness>
            <damping>0</damping>
            <friction>0</friction>
          </dynamics>
        </axis>
        <physics>
          <ode>
            <limit>
              <cfm>0</cfm>
              <erp>0.2</erp>
            </limit>
            <suspension>
              <cfm>0</cfm>
              <erp>0.2</erp>
            </suspension>
          </ode>
        </physics>
      </joint>
      <static>0</static>
      <allow_auto_disable>1</allow_auto_disable>
      <plugin name='omni_plugin' filename='/home/minhhud/projectPath/libmain.so'/>
      <pose frame=''>0 0 0 0 -0 0</pose>
    </model>
    <state world_name='default'>
      <sim_time>9 855000000</sim_time>
      <real_time>36 182329105</real_time>
      <wall_time>1510060811 581969097</wall_time>
      <iterations>9855</iterations>
      <model name='ground_plane'>
        <pose frame=''>0 0 0 0 -0 0</pose>
        <scale>1 1 1</scale>
        <link name='link'>
          <pose frame=''>0 0 0 0 -0 0</pose>
          <velocity>0 0 0 0 -0 0</velocity>
          <acceleration>0 0 0 0 -0 0</acceleration>
          <wrench>0 0 0 0 -0 0</wrench>
        </link>
      </model>
      <model name='omni_silbot'>
        <pose frame=''>-0.066771 -0.038946 0.023627 -0.015763 -0.030988 0.100963</pose>
        <scale>1 1 1</scale>
        <link name='link_1'>
          <pose frame=''>-0.06748 -0.038278 0.023595 -0.015763 -0.030988 0.100963</pose>
          <velocity>0.037149 -0.008186 -0.211808 -0.270757 -0.170414 0.552492</velocity>
          <acceleration>5.7097 3.78355 -13.8538 3.00595 -0.697522 -0.173348</acceleration>
          <wrench>5.7097 3.78355 -13.8538 0 -0 0</wrench>
        </link>
        <model name='omni_wheel_model'>
          <pose frame=''>-0.149207 -0.091032 0 0 -0 0.469574</pose>
          <scale>1 1 1</scale>
          <link name='omni_wheel_rim_link'>
            <pose frame=''>-0.205551 -0.144848 0.018155 -1.32642 -0.081297 0.218781</pose>
            <velocity>-0.196402 -0.18307 -0.070167 -0.746901 -0.260052 -0.995361</velocity>
            <acceleration>-277.409 -79.5961 126.752 -0.260475 0.716184 -1.66803</acceleration>
            <wrench>-2.31847 -0.66523 1.05934 0 -0 0</wrench>
          </link>
          <link name='omni_wheel_roller_e_link'>
            <pose frame=''>-0.209282 -0.144146 0.000234 -1.42322 0.378738 0.409675</pose>
            <velocity>-0.422998 -0.871164 0.226088 1.99841 1.20706 3.13767</velocity>
            <acceleration>-272.696 -575.117 313.302 0.000473 -0.599861 2.79004</acceleration>
            <wrench>-0.310451 -0.654742 0.356678 0 -0 0</wrench>
          </link>
          <link name='omni_wheel_roller_n_link'>
            <pose frame=''>-0.219013 -0.13573 0.02467 -0.224272 0.055362 -1.93742</pose>
            <velocity>0.325679 0.039432 -0.525933 0.881397 -0.046488 -1.30859</velocity>
            <acceleration>326.551 279.802 -489.241 -2.44389 -1.47807 0.252826</acceleration>
            <wrench>0.371762 0.318541 -0.556977 0 -0 0</wrench>
          </link>
          <link name='omni_wheel_roller_ne_link'>
            <pose frame=''>-0.195906 -0.127726 0.012163 -0.306717 0.620945 1.83038</pose>
            <velocity>-2.82002 -0.950973 -0.401296 -2.27497 0.345149 1.207</velocity>
            <acceleration>-3289.37 -623.03 -1153.1 3.12643 1.17992 2.2714</acceleration>
            <wrench>-3.74479 -0.709289 -1.31275 0 -0 0</wrench>
          </link>
          <link name='omni_wheel_roller_nw_link'>
            <pose frame=''>-0.205665 -0.134615 0.03261 0.450237 -0.899603 1.69406</pose>
            <velocity>0.137295 0.292925 -0.451065 0.233131 0.452232 -2.57004</velocity>
            <acceleration>89.1737 718.272 -380.468 0.030694 -0.293409 -2.97124</acceleration>
            <wrench>0.10152 0.817717 -0.433144 0 -0 0</wrench>
          </link>
          <link name='omni_wheel_roller_s_link'>
            <pose frame=''>-0.213924 -0.160984 0.009379 2.68552 -0.09658 -1.6657</pose>
            <velocity>0.000368 -0.267532 0.467943 -2.88338 0.238632 0.588421</velocity>
            <acceleration>-436.104 -825.137 537.505 0.223259 -1.39372 -2.93461</acceleration>
            <wrench>-0.496482 -0.939377 0.611923 0 -0 0</wrench>
          </link>
          <link name='omni_wheel_roller_se_link'>
            <pose frame=''>-0.192913 -0.153367 0.004265 -1.68944 0.001119 0.331924</pose>
            <velocity>-0.087598 -0.455762 0.224741 1.29525 -1.14927 -0.571027</velocity>
            <acceleration>-255.213 -718.025 854.825 2.94204 1.21521 -0.652749</acceleration>
            <wrench>-0.290548 -0.817435 0.973175 0 -0 0</wrench>
          </link>
          <link name='omni_wheel_roller_sw_link'>
            <pose frame=''>-0.193629 -0.151456 0.028597 -2.63879 0.147014 -2.79167</pose>
            <velocity>-0.076793 0.1089 0.230401 -1.04062 -1.28272 -0.277214</velocity>
            <acceleration>-124.054 329.389 767.574 1.20401 -0.386136 -2.49267</acceleration>
            <wrench>-0.14123 0.374993 0.873845 0 -0 0</wrench>
          </link>
          <link name='omni_wheel_roller_w_link'>
            <pose frame=''>-0.208884 -0.151129 0.034423 2.05639 -0.914229 0.258478</pose>
            <velocity>-0.044484 0.453514 -0.167246 -2.00969 -0.26855 0.422819</velocity>
            <acceleration>-124.39 830.038 149.782 -0.831443 0.361061 -0.196223</acceleration>
            <wrench>-0.141612 0.944957 0.170519 0 -0 0</wrench>
          </link>
        </model>
        <model name='omni_wheel_model_0'>
          <pose frame=''>-0.001547 0.174632 0 0 -0 1.52507</pose>
          <scale>1 1 1</scale>
          <link name='omni_wheel_rim_link'>
            <pose frame=''>-0.085166 0.134726 0.018485 -0.936043 -0.099927 1.61705</pose>
            <velocity>-0.066246 0.005459 -0.219526 1.68084 -0.699187 -3.00807</velocity>
            <acceleration>5.3912 28.2589 24.3453 -1.5891 0.870822 2.31042</acceleration>
            <wrench>0.045057 0.236176 0.203468 0 -0 0</wrench>
          </link>
          <link name='omni_wheel_roller_e_link'>
            <pose frame=''>-0.098301 0.127812 0.002434 -1.15188 0.738741 2.00651</pose>
            <velocity>0.885942 0.190285 0.032284 2.84871 0.859935 -1.45048</velocity>
            <acceleration>-175.529 68.5885 165.313 0.286348 0.914245 0.982079</acceleration>
            <wrench>-0.199832 0.078085 0.188201 0 -0 0</wrench>
          </link>
          <link name='omni_wheel_roller_n_link'>
            <pose frame=''>-0.097185 0.128615 0.030309 0.630539 -0.153019 1.90041</pose>
            <velocity>0.289678 -0.049289 0.005911 -0.027174 -1.39535 -0.634962</velocity>
            <acceleration>1179.15 -119.659 1714.94 -2.86549 0.698701 -2.85098</acceleration>
            <wrench>1.3424 -0.136226 1.95238 0 -0 0</wrench>
          </link>
          <link name='omni_wheel_roller_ne_link'>
            <pose frame=''>-0.100323 0.138894 0.018308 -0.166639 -0.039795 0.113349</pose>
            <velocity>-0.033822 0.019097 -0.036681 1.50564 -0.500067 -0.03205</velocity>
            <acceleration>-298.201 -315.276 1867.65 2.64691 -1.47285 -1.95247</acceleration>
            <wrench>-0.339487 -0.358926 2.12623 0 -0 0</wrench>
          </link>
          <link name='omni_wheel_roller_nw_link'>
            <pose frame=''>-0.088434 0.140538 0.035462 1.39868 0.584831 1.54899</pose>
            <velocity>0.366332 0.007261 -0.324054 1.74048 0.663543 -2.11728</velocity>
            <acceleration>1929.45 133.873 307.102 2.64466 -0.626701 0.557385</acceleration>
            <wrench>2.19659 0.152407 0.349621 0 -0 0</wrench>
          </link>
          <link name='omni_wheel_roller_s_link'>
            <pose frame=''>-0.06808 0.131869 0.00327 -2.13439 1.15967 0.788459</pose>
            <velocity>-0.258228 0.119154 -0.698654 -2.05262 1.56045 2.49827</velocity>
            <acceleration>319.794 707.934 -3474.64 1.62656 -1.14102 0.887168</acceleration>
            <wrench>0.36407 0.805947 -3.9557 0 -0 0</wrench>
          </link>
          <link name='omni_wheel_roller_se_link'>
            <pose frame=''>-0.078312 0.141124 0.003851 -1.4028 0.611391 1.46661</pose>
            <velocity>-0.515402 -0.142724 0.443357 2.29521 1.2798 -0.099065</velocity>
            <acceleration>-475.628 -23.4409 132.896 1.19899 -0.343137 0.13669</acceleration>
            <wrench>-0.541479 -0.026686 0.151295 0 -0 0</wrench>
          </link>
          <link name='omni_wheel_roller_sw_link'>
            <pose frame=''>-0.072151 0.141111 0.023318 3.0813 -0.139816 0.205151</pose>
            <velocity>-0.121011 0.038586 -0.695392 0.918442 0.273608 -2.68748</velocity>
            <acceleration>178.922 258.891 -1931.74 1.61181 -1.23594 1.18745</acceleration>
            <wrench>0.203694 0.294734 -2.19918 0 -0 0</wrench>
          </link>
          <link name='omni_wheel_roller_w_link'>
            <pose frame=''>-0.077177 0.130073 0.033327 2.33823 0.544559 2.07044</pose>
            <velocity>0.206923 0.041484 -0.595697 1.15238 -0.585549 3.0101</velocity>
            <acceleration>1517.71 286.675 -1089 -2.81118 0.195697 -3.07036</acceleration>
            <wrench>1.72784 0.326365 -1.23978 0 -0 0</wrench>
          </link>
        </model>
        <model name='omni_wheel_model_1'>
          <pose frame=''>0.152263 -0.085749 0 0 0 -0.499135</pose>
          <scale>1 1 1</scale>
          <link name='omni_wheel_rim_link'>
            <pose frame=''>0.09438 -0.109105 0.027462 -0.480592 -0.157621 -0.243534</pose>
            <velocity>0.012558 0.096672 0.405553 -1.70546 -0.057267 -1.70329</velocity>
            <acceleration>-52.1051 -6.63697 510.666 0.73102 -0.149776 -0.689993</acceleration>
            <wrench>-0.435473 -0.055469 4.26793 0 -0 0</wrench>
          </link>
          <link name='omni_wheel_roller_e_link'>
            <pose frame=''>0.092781 -0.09388 0.014374 -0.66311 0.761005 0.613145</pose>
            <velocity>-0.104554 0.740232 3.54785 3.10086 1.55802 0.480012</velocity>
            <acceleration>514.752 444.076 4252.41 -0.129721 0.927431 -0.040149</acceleration>
            <wrench>0.586019 0.505558 4.84115 0 -0 0</wrench>
          </link>
          <link name='omni_wheel_roller_n_link'>
            <pose frame=''>0.089673 -0.102252 0.042939 -0.726346 1.01765 -2.61481</pose>
            <velocity>-0.647341 -1.03509 0.705256 0.274906 0.830749 1.7937</velocity>
            <acceleration>-742.108 -1185.75 702.683 -2.26687 -0.575197 1.0267</acceleration>
            <wrench>-0.844852 -1.34992 0.799969 0 -0 0</wrench>
          </link>
          <link name='omni_wheel_roller_ne_link'>
            <pose frame=''>0.102203 -0.097612 0.034851 0.328541 0.399675 -0.919336</pose>
            <velocity>-0.362072 0.024643 1.60483 -2.72039 0.717311 -0.775299</velocity>
            <acceleration>-499.726 137.405 1477.51 -1.04241 -0.752943 0.207345</acceleration>
            <wrench>-0.568914 0.156429 1.68207 0 -0 0</wrench>
          </link>
          <link name='omni_wheel_roller_nw_link'>
            <pose frame=''>0.098154 -0.115542 0.043384 -2.97893 -1.19343 -1.96803</pose>
            <velocity>-0.512081 -1.30232 -0.313987 -2.02518 -1.17515 -2.96815</velocity>
            <acceleration>-396.348 -1254.91 -187.51 -0.517733 0.902713 -1.07516</acceleration>
            <wrench>-0.451223 -1.42865 -0.21347 0 -0 0</wrench>
          </link>
          <link name='omni_wheel_roller_s_link'>
            <pose frame=''>0.089334 -0.115151 0.009079 -1.93268 0.886771 -0.597945</pose>
            <velocity>0.361198 1.43751 0.007781 -0.063249 1.46774 1.69817</velocity>
            <acceleration>1357.66 702.967 331.33 -2.94475 -1.1429 -1.14598</acceleration>
            <wrench>1.54563 0.800293 0.377202 0 -0 0</wrench>
          </link>
          <link name='omni_wheel_roller_se_link'>
            <pose frame=''>0.102909 -0.107432 0.011922 -1.43237 0.233695 -0.163077</pose>
            <velocity>0.272163 2.21048 1.41767 -2.42927 0.770707 -2.50793</velocity>
            <acceleration>549.528 2129.01 1751.49 -0.623024 0.644948 2.99928</acceleration>
            <wrench>0.62561 2.42377 1.99399 0 -0 0</wrench>
          </link>
          <link name='omni_wheel_roller_sw_link'>
            <pose frame=''>0.102616 -0.12483 0.024054 -2.90733 -0.127469 0.222403</pose>
            <velocity>0.308181 0.885948 -0.296113 2.4943 -0.430671 3.01671</velocity>
            <acceleration>1237.73 371.425 -31.647 -1.65976 -0.715134 -0.672689</acceleration>
            <wrench>1.4091 0.422849 -0.036029 0 -0 0</wrench>
          </link>
          <link name='omni_wheel_roller_w_link'>
            <pose frame=''>0.085856 -0.120441 0.035758 2.82425 0.27874 0.505205</pose>
            <velocity>-0.015733 -0.833854 -1.49684 -1.59383 0.48324 2.8803</velocity>
            <acceleration>215.523 -1119.41 -1311.8 -2.01793 1.12587 0.883613</acceleration>
            <wrench>0.245362 -1.27439 -1.49341 0 -0 0</wrench>
          </link>
        </model>
      </model>
      <light name='sun'>
        <pose frame=''>0 0 10 0 -0 0</pose>
      </light>
    </state>
    <gui fullscreen='0'>
      <camera name='user_camera'>
        <pose frame=''>5 -5 2 0 0.275643 2.35619</pose>
        <view_controller>orbit</view_controller>
        <projection_type>perspective</projection_type>
      </camera>
    </gui>
  </world>
</sdf>
