<?xml version='1.0'?>
<sdf version='1.6'>
  <model name='URDF_Silbot'>
    <link name='base_link'>
      <pose frame=''>0 0 0 0 -0 0</pose>
      <inertial>
        <pose frame=''>1e-06 0.303247 -0.02402 0 -0 0</pose>
        <mass>62.7691</mass>
        <inertia>
          <ixx>4.50843</ixx>
          <ixy>-1.06127e-05</ixy>
          <ixz>-0.000498782</ixz>
          <iyy>1.12013</iyy>
          <iyz>0.214466</iyz>
          <izz>4.45203</izz>
        </inertia>
      </inertial>
      <collision name='base_link_collision'>
        <pose frame=''>0 0 0 0 -0 0</pose>
        <geometry>
          <mesh>
            <scale>1 1 1</scale>
            <uri>model://silbot3_description/meshes/base_link.stl</uri>
          </mesh>
        </geometry>
      </collision>
      <visual name='base_link_visual'>
        <pose frame=''>0 0 0 0 -0 0</pose>
        <geometry>
          <mesh>
            <scale>1 1 1</scale>
            <uri>model://silbot3_description/meshes/base_link.stl</uri>
          </mesh>
        </geometry>
      </visual>
    </link>
    <link name='head_pan'>
      <pose frame=''>0 0.027 0.882 1.5708 -0 0</pose>
      <inertial>
        <pose frame=''>-0 0.043444 0 0 -0 0</pose>
        <mass>0.0271785</mass>
        <inertia>
          <ixx>1.80958e-05</ixx>
          <ixy>1.89946e-21</ixy>
          <ixz>-2.48737e-11</ixz>
          <iyy>1.43652e-06</iyy>
          <iyz>-1.5576e-12</iyz>
          <izz>1.80877e-05</izz>
        </inertia>
      </inertial>
      <collision name='head_pan_collision'>
        <pose frame=''>0 0 0 0 -0 0</pose>
        <geometry>
          <mesh>
            <scale>1 1 1</scale>
            <uri>model://silbot3_description/meshes/head_pan.stl</uri>
          </mesh>
        </geometry>
      </collision>
      <visual name='head_pan_visual'>
        <pose frame=''>0 0 0 0 -0 0</pose>
        <geometry>
          <mesh>
            <scale>1 1 1</scale>
            <uri>model://silbot3_description/meshes/head_pan.stl</uri>
          </mesh>
        </geometry>
      </visual>
    </link>
    <joint name='head_pan' type='revolute'>
      <child>head_pan</child>
      <parent>base_link</parent>
      <axis>
        <xyz>0 -0 1</xyz>
        <limit>
          <lower>-1e+16</lower>
          <upper>1e+16</upper>
        </limit>
        <dynamics>
          <spring_reference>0</spring_reference>
          <spring_stiffness>0</spring_stiffness>
        </dynamics>
        <use_parent_model_frame>1</use_parent_model_frame>
      </axis>
    </joint>
    <link name='head_tilt'>
      <pose frame=''>0 0.027 0.962 1.5708 -0 0</pose>
      <inertial>
        <pose frame=''>0 0.00018 0.098466 0 -0 0</pose>
        <mass>3.1958</mass>
        <inertia>
          <ixx>0.016128</ixx>
          <ixy>-3.74549e-07</ixy>
          <ixz>4.1057e-08</ixz>
          <iyy>0.0120784</iyy>
          <iyz>6.02015e-05</iyz>
          <izz>0.0190875</izz>
        </inertia>
      </inertial>
      <collision name='head_tilt_collision'>
        <pose frame=''>0 0 0 0 -0 0</pose>
        <geometry>
          <mesh>
            <scale>1 1 1</scale>
            <uri>model://silbot3_description/meshes/head_tilt.stl</uri>
          </mesh>
        </geometry>
      </collision>
      <visual name='head_tilt_visual'>
        <pose frame=''>0 0 0 0 -0 0</pose>
        <geometry>
          <mesh>
            <scale>1 1 1</scale>
            <uri>model://silbot3_description/meshes/head_tilt.stl</uri>
          </mesh>
        </geometry>
      </visual>
    </link>
    <joint name='head_tilt' type='revolute'>
      <child>head_tilt</child>
      <parent>head_pan</parent>
      <axis>
        <xyz>-1 0 0</xyz>
        <limit>
          <lower>-1e+16</lower>
          <upper>1e+16</upper>
        </limit>
        <dynamics>
          <spring_reference>0</spring_reference>
          <spring_stiffness>0</spring_stiffness>
        </dynamics>
        <use_parent_model_frame>1</use_parent_model_frame>
      </axis>
    </joint>
    <link name='laser_link'>
      <pose frame=''>0 -0.15 0.25 0 -0 0</pose>
      <inertial>
        <pose frame=''>0.2 0 0.2 0 -0 0</pose>
        <mass>62.7691</mass>
        <inertia>
          <ixx>4.50843</ixx>
          <ixy>-1.06127e-05</ixy>
          <ixz>-0.000498782</ixz>
          <iyy>1.12013</iyy>
          <iyz>0.214466</iyz>
          <izz>4.45203</izz>
        </inertia>
      </inertial>
      <collision name='laser_link_collision'>
        <pose frame=''>0 0 0 0 -0 0</pose>
        <geometry>
          <mesh>
            <scale>1 1 1</scale>
            <uri>model://silbot3_description/meshes/front_lrf.stl</uri>
          </mesh>
        </geometry>
      </collision>
      <visual name='laser_link_visual'>
        <pose frame=''>0 0 0 0 -0 0</pose>
        <geometry>
          <mesh>
            <scale>1 1 1</scale>
            <uri>model://silbot3_description/meshes/front_lrf.stl</uri>
          </mesh>
        </geometry>
      </visual>
    </link>
    <joint name='laser_link' type='revolute'>
      <child>laser_link</child>
      <parent>base_link</parent>
      <axis>
        <xyz>0 1 0</xyz>
        <limit>
          <lower>-1e+16</lower>
          <upper>1e+16</upper>
        </limit>
        <dynamics>
          <spring_reference>0</spring_reference>
          <spring_stiffness>0</spring_stiffness>
        </dynamics>
        <use_parent_model_frame>1</use_parent_model_frame>
      </axis>
    </joint>
    <link name='left_shoulder_roll'>
      <pose frame=''>0.13 0.04 0.68 1.5708 -0 0</pose>
      <inertial>
        <pose frame=''>0.040224 0 -0 0 -0 0</pose>
        <mass>0.52377</mass>
        <inertia>
          <ixx>0.000508939</ixx>
          <ixy>1.2276e-11</ixy>
          <ixz>-3.81706e-10</ixz>
          <iyy>0.00069487</iyy>
          <iyz>8.2592e-11</iyz>
          <izz>0.000695111</izz>
        </inertia>
      </inertial>
      <collision name='left_shoulder_roll_collision'>
        <pose frame=''>0 0 0 0 -0 0</pose>
        <geometry>
          <mesh>
            <scale>1 1 1</scale>
            <uri>model://silbot3_description/meshes/left_shoulder_roll.stl</uri>
          </mesh>
        </geometry>
      </collision>
      <visual name='left_shoulder_roll_visual'>
        <pose frame=''>0 0 0 0 -0 0</pose>
        <geometry>
          <mesh>
            <scale>1 1 1</scale>
            <uri>model://silbot3_description/meshes/left_shoulder_roll.stl</uri>
          </mesh>
        </geometry>
      </visual>
    </link>
    <joint name='left_shoulder_roll' type='revolute'>
      <child>left_shoulder_roll</child>
      <parent>base_link</parent>
      <axis>
        <xyz>-1 0 0</xyz>
        <limit>
          <lower>-1e+16</lower>
          <upper>1e+16</upper>
        </limit>
        <dynamics>
          <spring_reference>0</spring_reference>
          <spring_stiffness>0</spring_stiffness>
        </dynamics>
        <use_parent_model_frame>1</use_parent_model_frame>
      </axis>
    </joint>
    <link name='left_shoulder_pitch'>
      <pose frame=''>0.21 0.04 0.68 1.5708 -0 0</pose>
      <inertial>
        <pose frame=''>0.004472 -0.060881 0 0 -0 0</pose>
        <mass>0.464234</mass>
        <inertia>
          <ixx>0.00110738</ixx>
          <ixy>-3.01463e-06</ixy>
          <ixz>6.73343e-13</ixz>
          <iyy>0.000491854</iyy>
          <iyz>1.01557e-11</iyz>
          <izz>0.000794792</izz>
        </inertia>
      </inertial>
      <collision name='left_shoulder_pitch_collision'>
        <pose frame=''>0 0 0 0 -0 0</pose>
        <geometry>
          <mesh>
            <scale>1 1 1</scale>
            <uri>model://silbot3_description/meshes/left_shoulder_pitch.stl</uri>
          </mesh>
        </geometry>
      </collision>
      <visual name='left_shoulder_pitch_visual'>
        <pose frame=''>0 0 0 0 -0 0</pose>
        <geometry>
          <mesh>
            <scale>1 1 1</scale>
            <uri>model://silbot3_description/meshes/left_shoulder_pitch.stl</uri>
          </mesh>
        </geometry>
      </visual>
    </link>
    <joint name='left_shoulder_pitch' type='revolute'>
      <child>left_shoulder_pitch</child>
      <parent>left_shoulder_roll</parent>
      <axis>
        <xyz>0 -1 -0</xyz>
        <limit>
          <lower>-1e+16</lower>
          <upper>1e+16</upper>
        </limit>
        <dynamics>
          <spring_reference>0</spring_reference>
          <spring_stiffness>0</spring_stiffness>
        </dynamics>
        <use_parent_model_frame>1</use_parent_model_frame>
      </axis>
    </joint>
    <link name='left_elbow_pitch'>
      <pose frame=''>0.21 0.04 0.56 1.5708 -0 0</pose>
      <inertial>
        <pose frame=''>-0.002738 -0.099275 -0 0 -0 0</pose>
        <mass>0.793075</mass>
        <inertia>
          <ixx>0.00370912</ixx>
          <ixy>-0.000111595</ixy>
          <ixz>-1.37331e-09</ixz>
          <iyy>0.000538057</iyy>
          <iyz>6.96383e-11</iyz>
          <izz>0.00343366</izz>
        </inertia>
      </inertial>
      <collision name='left_elbow_pitch_collision'>
        <pose frame=''>0 0 0 0 -0 0</pose>
        <geometry>
          <mesh>
            <scale>1 1 1</scale>
            <uri>model://silbot3_description/meshes/left_elbow_pitch.stl</uri>
          </mesh>
        </geometry>
      </collision>
      <visual name='left_elbow_pitch_visual'>
        <pose frame=''>0 0 0 0 -0 0</pose>
        <geometry>
          <mesh>
            <scale>1 1 1</scale>
            <uri>model://silbot3_description/meshes/left_elbow_pitch.stl</uri>
          </mesh>
        </geometry>
      </visual>
    </link>
    <joint name='left_elbow_pitch' type='revolute'>
      <child>left_elbow_pitch</child>
      <parent>left_shoulder_pitch</parent>
      <axis>
        <xyz>0 -1 -0</xyz>
        <limit>
          <lower>-1e+16</lower>
          <upper>1e+16</upper>
        </limit>
        <dynamics>
          <spring_reference>0</spring_reference>
          <spring_stiffness>0</spring_stiffness>
        </dynamics>
        <use_parent_model_frame>1</use_parent_model_frame>
      </axis>
    </joint>
    <link name='right_shoulder_roll'>
      <pose frame=''>-0.13 0.04 0.68 1.5708 -0 3.14159</pose>
      <inertial>
        <pose frame=''>0.040224 0 -0 0 -0 0</pose>
        <mass>0.52377</mass>
        <inertia>
          <ixx>0.000508939</ixx>
          <ixy>1.2276e-11</ixy>
          <ixz>-3.81706e-10</ixz>
          <iyy>0.00069487</iyy>
          <iyz>8.2592e-11</iyz>
          <izz>0.000695111</izz>
        </inertia>
      </inertial>
      <collision name='right_shoulder_roll_collision'>
        <pose frame=''>0 0 0 0 -0 0</pose>
        <geometry>
          <mesh>
            <scale>1 1 1</scale>
            <uri>model://silbot3_description/meshes/right_shoulder_roll.stl</uri>
          </mesh>
        </geometry>
      </collision>
      <visual name='right_shoulder_roll_visual'>
        <pose frame=''>0 0 0 0 -0 0</pose>
        <geometry>
          <mesh>
            <scale>1 1 1</scale>
            <uri>model://silbot3_description/meshes/right_shoulder_roll.stl</uri>
          </mesh>
        </geometry>
      </visual>
    </link>
    <joint name='right_shoulder_roll' type='revolute'>
      <child>right_shoulder_roll</child>
      <parent>base_link</parent>
      <axis>
        <xyz>-1 0 0</xyz>
        <limit>
          <lower>-1e+16</lower>
          <upper>1e+16</upper>
        </limit>
        <dynamics>
          <spring_reference>0</spring_reference>
          <spring_stiffness>0</spring_stiffness>
        </dynamics>
        <use_parent_model_frame>1</use_parent_model_frame>
      </axis>
    </joint>
    <link name='right_shoulder_pitch'>
      <pose frame=''>-0.21 0.04 0.68 1.5708 -0 3.14159</pose>
      <inertial>
        <pose frame=''>0.004472 -0.060881 0 0 -0 0</pose>
        <mass>0.464234</mass>
        <inertia>
          <ixx>0.00110738</ixx>
          <ixy>-3.01463e-06</ixy>
          <ixz>6.73342e-13</ixz>
          <iyy>0.000491854</iyy>
          <iyz>1.01557e-11</iyz>
          <izz>0.000794792</izz>
        </inertia>
      </inertial>
      <collision name='right_shoulder_pitch_collision'>
        <pose frame=''>0 0 0 0 -0 0</pose>
        <geometry>
          <mesh>
            <scale>1 1 1</scale>
            <uri>model://silbot3_description/meshes/right_shoulder_pitch.stl</uri>
          </mesh>
        </geometry>
      </collision>
      <visual name='right_shoulder_pitch_visual'>
        <pose frame=''>0 0 0 0 -0 0</pose>
        <geometry>
          <mesh>
            <scale>1 1 1</scale>
            <uri>model://silbot3_description/meshes/right_shoulder_pitch.stl</uri>
          </mesh>
        </geometry>
      </visual>
    </link>
    <joint name='right_shoulder_pitch' type='revolute'>
      <child>right_shoulder_pitch</child>
      <parent>right_shoulder_roll</parent>
      <axis>
        <xyz>0 1 -0</xyz>
        <limit>
          <lower>-1e+16</lower>
          <upper>1e+16</upper>
        </limit>
        <dynamics>
          <spring_reference>0</spring_reference>
          <spring_stiffness>0</spring_stiffness>
        </dynamics>
        <use_parent_model_frame>1</use_parent_model_frame>
      </axis>
    </joint>
    <link name='right_elbow_pitch'>
      <pose frame=''>-0.21 0.04 0.56 1.5708 -0 3.14159</pose>
      <inertial>
        <pose frame=''>-0.002738 -0.099275 -0 0 -0 0</pose>
        <mass>0.793075</mass>
        <inertia>
          <ixx>0.00370912</ixx>
          <ixy>-0.000111595</ixy>
          <ixz>-1.37331e-09</ixz>
          <iyy>0.000538057</iyy>
          <iyz>6.96383e-11</iyz>
          <izz>0.00343366</izz>
        </inertia>
      </inertial>
      <collision name='right_elbow_pitch_collision'>
        <pose frame=''>0 0 0 0 -0 0</pose>
        <geometry>
          <mesh>
            <scale>1 1 1</scale>
            <uri>model://silbot3_description/meshes/right_elbow_pitch.stl</uri>
          </mesh>
        </geometry>
      </collision>
      <visual name='right_elbow_pitch_visual'>
        <pose frame=''>0 0 0 0 -0 0</pose>
        <geometry>
          <mesh>
            <scale>1 1 1</scale>
            <uri>model://silbot3_description/meshes/right_elbow_pitch.stl</uri>
          </mesh>
        </geometry>
      </visual>
    </link>
    <joint name='right_elbow_pitch' type='revolute'>
      <child>right_elbow_pitch</child>
      <parent>right_shoulder_pitch</parent>
      <axis>
        <xyz>0 11 -0</xyz>
        <limit>
          <lower>-1e+16</lower>
          <upper>1e+16</upper>
        </limit>
        <dynamics>
          <spring_reference>0</spring_reference>
          <spring_stiffness>0</spring_stiffness>
        </dynamics>
        <use_parent_model_frame>1</use_parent_model_frame>
      </axis>
    </joint>
  </model>
</sdf>

